ERROR 2024-12-08 14:28:14,171 log Internal Server Error: /common/currentuser/
Traceback (most recent call last):
  File "/usr/local/lib/python3.13/site-packages/django/db/backends/utils.py", line 105, in _execute
    return self.cursor.execute(sql, params)
           ~~~~~~~~~~~~~~~~~~~^^^^^^^^^^^^^
  File "/usr/local/lib/python3.13/site-packages/django/db/backends/sqlite3/base.py", line 354, in execute
    return super().execute(query, params)
           ~~~~~~~~~~~~~~~^^^^^^^^^^^^^^^
sqlite3.OperationalError: no such table: common_userprofile

The above exception was the direct cause of the following exception:

Traceback (most recent call last):
  File "/usr/local/lib/python3.13/site-packages/django/core/handlers/exception.py", line 55, in inner
    response = get_response(request)
  File "/usr/local/lib/python3.13/site-packages/django/core/handlers/base.py", line 197, in _get_response
    response = wrapped_callback(request, *callback_args, **callback_kwargs)
  File "/usr/local/lib/python3.13/site-packages/django/views/decorators/csrf.py", line 65, in _view_wrapper
    return view_func(request, *args, **kwargs)
  File "/usr/local/lib/python3.13/site-packages/django/views/generic/base.py", line 104, in view
    return self.dispatch(request, *args, **kwargs)
           ~~~~~~~~~~~~~^^^^^^^^^^^^^^^^^^^^^^^^^^
  File "/usr/local/lib/python3.13/site-packages/rest_framework/views.py", line 509, in dispatch
    response = self.handle_exception(exc)
  File "/usr/local/lib/python3.13/site-packages/rest_framework/views.py", line 469, in handle_exception
    self.raise_uncaught_exception(exc)
    ~~~~~~~~~~~~~~~~~~~~~~~~~~~~~^^^^^
  File "/usr/local/lib/python3.13/site-packages/rest_framework/views.py", line 480, in raise_uncaught_exception
    raise exc
  File "/usr/local/lib/python3.13/site-packages/rest_framework/views.py", line 506, in dispatch
    response = handler(request, *args, **kwargs)
  File "/app/common/views.py", line 89, in get
    userprofile = UserProfile.objects.get(user=user)
  File "/usr/local/lib/python3.13/site-packages/django/db/models/manager.py", line 87, in manager_method
    return getattr(self.get_queryset(), name)(*args, **kwargs)
           ~~~~~~~~~~~~~~~~~~~~~~~~~~~~~~~~~~^^^^^^^^^^^^^^^^^
  File "/usr/local/lib/python3.13/site-packages/django/db/models/query.py", line 645, in get
    num = len(clone)
  File "/usr/local/lib/python3.13/site-packages/django/db/models/query.py", line 382, in __len__
    self._fetch_all()
    ~~~~~~~~~~~~~~~^^
  File "/usr/local/lib/python3.13/site-packages/django/db/models/query.py", line 1928, in _fetch_all
    self._result_cache = list(self._iterable_class(self))
                         ~~~~^^^^^^^^^^^^^^^^^^^^^^^^^^^^
  File "/usr/local/lib/python3.13/site-packages/django/db/models/query.py", line 91, in __iter__
    results = compiler.execute_sql(
        chunked_fetch=self.chunked_fetch, chunk_size=self.chunk_size
    )
  File "/usr/local/lib/python3.13/site-packages/django/db/models/sql/compiler.py", line 1574, in execute_sql
    cursor.execute(sql, params)
    ~~~~~~~~~~~~~~^^^^^^^^^^^^^
  File "/usr/local/lib/python3.13/site-packages/django/db/backends/utils.py", line 122, in execute
    return super().execute(sql, params)
           ~~~~~~~~~~~~~~~^^^^^^^^^^^^^
  File "/usr/local/lib/python3.13/site-packages/django/db/backends/utils.py", line 79, in execute
    return self._execute_with_wrappers(
           ~~~~~~~~~~~~~~~~~~~~~~~~~~~^
        sql, params, many=False, executor=self._execute
        ^^^^^^^^^^^^^^^^^^^^^^^^^^^^^^^^^^^^^^^^^^^^^^^
    )
    ^
  File "/usr/local/lib/python3.13/site-packages/django/db/backends/utils.py", line 92, in _execute_with_wrappers
    return executor(sql, params, many, context)
  File "/usr/local/lib/python3.13/site-packages/django/db/backends/utils.py", line 100, in _execute
    with self.db.wrap_database_errors:
         ^^^^^^^^^^^^^^^^^^^^^^^^^^^^
  File "/usr/local/lib/python3.13/site-packages/django/db/utils.py", line 91, in __exit__
    raise dj_exc_value.with_traceback(traceback) from exc_value
  File "/usr/local/lib/python3.13/site-packages/django/db/backends/utils.py", line 105, in _execute
    return self.cursor.execute(sql, params)
           ~~~~~~~~~~~~~~~~~~~^^^^^^^^^^^^^
  File "/usr/local/lib/python3.13/site-packages/django/db/backends/sqlite3/base.py", line 354, in execute
    return super().execute(query, params)
           ~~~~~~~~~~~~~~~^^^^^^^^^^^^^^^
django.db.utils.OperationalError: no such table: common_userprofile
ERROR 2024-12-08 14:28:14,183 basehttp "GET /common/currentuser/ HTTP/1.1" 500 158902
ERROR 2024-12-08 14:36:31,726 log Internal Server Error: /common/currentuser/
Traceback (most recent call last):
  File "/usr/local/lib/python3.13/site-packages/django/db/backends/utils.py", line 105, in _execute
    return self.cursor.execute(sql, params)
           ~~~~~~~~~~~~~~~~~~~^^^^^^^^^^^^^
  File "/usr/local/lib/python3.13/site-packages/django/db/backends/sqlite3/base.py", line 354, in execute
    return super().execute(query, params)
           ~~~~~~~~~~~~~~~^^^^^^^^^^^^^^^
sqlite3.OperationalError: no such table: common_userprofile

The above exception was the direct cause of the following exception:

Traceback (most recent call last):
  File "/usr/local/lib/python3.13/site-packages/django/core/handlers/exception.py", line 55, in inner
    response = get_response(request)
  File "/usr/local/lib/python3.13/site-packages/django/core/handlers/base.py", line 197, in _get_response
    response = wrapped_callback(request, *callback_args, **callback_kwargs)
  File "/usr/local/lib/python3.13/site-packages/django/views/decorators/csrf.py", line 65, in _view_wrapper
    return view_func(request, *args, **kwargs)
  File "/usr/local/lib/python3.13/site-packages/django/views/generic/base.py", line 104, in view
    return self.dispatch(request, *args, **kwargs)
           ~~~~~~~~~~~~~^^^^^^^^^^^^^^^^^^^^^^^^^^
  File "/usr/local/lib/python3.13/site-packages/rest_framework/views.py", line 509, in dispatch
    response = self.handle_exception(exc)
  File "/usr/local/lib/python3.13/site-packages/rest_framework/views.py", line 469, in handle_exception
    self.raise_uncaught_exception(exc)
    ~~~~~~~~~~~~~~~~~~~~~~~~~~~~~^^^^^
  File "/usr/local/lib/python3.13/site-packages/rest_framework/views.py", line 480, in raise_uncaught_exception
    raise exc
  File "/usr/local/lib/python3.13/site-packages/rest_framework/views.py", line 506, in dispatch
    response = handler(request, *args, **kwargs)
  File "/app/common/views.py", line 89, in get
    userprofile = UserProfile.objects.get(user=user)
  File "/usr/local/lib/python3.13/site-packages/django/db/models/manager.py", line 87, in manager_method
    return getattr(self.get_queryset(), name)(*args, **kwargs)
           ~~~~~~~~~~~~~~~~~~~~~~~~~~~~~~~~~~^^^^^^^^^^^^^^^^^
  File "/usr/local/lib/python3.13/site-packages/django/db/models/query.py", line 645, in get
    num = len(clone)
  File "/usr/local/lib/python3.13/site-packages/django/db/models/query.py", line 382, in __len__
    self._fetch_all()
    ~~~~~~~~~~~~~~~^^
  File "/usr/local/lib/python3.13/site-packages/django/db/models/query.py", line 1928, in _fetch_all
    self._result_cache = list(self._iterable_class(self))
                         ~~~~^^^^^^^^^^^^^^^^^^^^^^^^^^^^
  File "/usr/local/lib/python3.13/site-packages/django/db/models/query.py", line 91, in __iter__
    results = compiler.execute_sql(
        chunked_fetch=self.chunked_fetch, chunk_size=self.chunk_size
    )
  File "/usr/local/lib/python3.13/site-packages/django/db/models/sql/compiler.py", line 1574, in execute_sql
    cursor.execute(sql, params)
    ~~~~~~~~~~~~~~^^^^^^^^^^^^^
  File "/usr/local/lib/python3.13/site-packages/django/db/backends/utils.py", line 122, in execute
    return super().execute(sql, params)
           ~~~~~~~~~~~~~~~^^^^^^^^^^^^^
  File "/usr/local/lib/python3.13/site-packages/django/db/backends/utils.py", line 79, in execute
    return self._execute_with_wrappers(
           ~~~~~~~~~~~~~~~~~~~~~~~~~~~^
        sql, params, many=False, executor=self._execute
        ^^^^^^^^^^^^^^^^^^^^^^^^^^^^^^^^^^^^^^^^^^^^^^^
    )
    ^
  File "/usr/local/lib/python3.13/site-packages/django/db/backends/utils.py", line 92, in _execute_with_wrappers
    return executor(sql, params, many, context)
  File "/usr/local/lib/python3.13/site-packages/django/db/backends/utils.py", line 100, in _execute
    with self.db.wrap_database_errors:
         ^^^^^^^^^^^^^^^^^^^^^^^^^^^^
  File "/usr/local/lib/python3.13/site-packages/django/db/utils.py", line 91, in __exit__
    raise dj_exc_value.with_traceback(traceback) from exc_value
  File "/usr/local/lib/python3.13/site-packages/django/db/backends/utils.py", line 105, in _execute
    return self.cursor.execute(sql, params)
           ~~~~~~~~~~~~~~~~~~~^^^^^^^^^^^^^
  File "/usr/local/lib/python3.13/site-packages/django/db/backends/sqlite3/base.py", line 354, in execute
    return super().execute(query, params)
           ~~~~~~~~~~~~~~~^^^^^^^^^^^^^^^
django.db.utils.OperationalError: no such table: common_userprofile
ERROR 2024-12-08 14:36:31,735 basehttp "GET /common/currentuser/ HTTP/1.1" 500 158902
ERROR 2024-12-08 14:37:29,551 log Internal Server Error: /common/currentuser/
Traceback (most recent call last):
  File "/usr/local/lib/python3.13/site-packages/django/db/backends/utils.py", line 105, in _execute
    return self.cursor.execute(sql, params)
           ~~~~~~~~~~~~~~~~~~~^^^^^^^^^^^^^
  File "/usr/local/lib/python3.13/site-packages/django/db/backends/sqlite3/base.py", line 354, in execute
    return super().execute(query, params)
           ~~~~~~~~~~~~~~~^^^^^^^^^^^^^^^
sqlite3.OperationalError: no such table: common_userprofile

The above exception was the direct cause of the following exception:

Traceback (most recent call last):
  File "/usr/local/lib/python3.13/site-packages/django/core/handlers/exception.py", line 55, in inner
    response = get_response(request)
  File "/usr/local/lib/python3.13/site-packages/django/core/handlers/base.py", line 197, in _get_response
    response = wrapped_callback(request, *callback_args, **callback_kwargs)
  File "/usr/local/lib/python3.13/site-packages/django/views/decorators/csrf.py", line 65, in _view_wrapper
    return view_func(request, *args, **kwargs)
  File "/usr/local/lib/python3.13/site-packages/django/views/generic/base.py", line 104, in view
    return self.dispatch(request, *args, **kwargs)
           ~~~~~~~~~~~~~^^^^^^^^^^^^^^^^^^^^^^^^^^
  File "/usr/local/lib/python3.13/site-packages/rest_framework/views.py", line 509, in dispatch
    response = self.handle_exception(exc)
  File "/usr/local/lib/python3.13/site-packages/rest_framework/views.py", line 469, in handle_exception
    self.raise_uncaught_exception(exc)
    ~~~~~~~~~~~~~~~~~~~~~~~~~~~~~^^^^^
  File "/usr/local/lib/python3.13/site-packages/rest_framework/views.py", line 480, in raise_uncaught_exception
    raise exc
  File "/usr/local/lib/python3.13/site-packages/rest_framework/views.py", line 506, in dispatch
    response = handler(request, *args, **kwargs)
  File "/app/common/views.py", line 89, in get
    userprofile = UserProfile.objects.get(user=user)
  File "/usr/local/lib/python3.13/site-packages/django/db/models/manager.py", line 87, in manager_method
    return getattr(self.get_queryset(), name)(*args, **kwargs)
           ~~~~~~~~~~~~~~~~~~~~~~~~~~~~~~~~~~^^^^^^^^^^^^^^^^^
  File "/usr/local/lib/python3.13/site-packages/django/db/models/query.py", line 645, in get
    num = len(clone)
  File "/usr/local/lib/python3.13/site-packages/django/db/models/query.py", line 382, in __len__
    self._fetch_all()
    ~~~~~~~~~~~~~~~^^
  File "/usr/local/lib/python3.13/site-packages/django/db/models/query.py", line 1928, in _fetch_all
    self._result_cache = list(self._iterable_class(self))
                         ~~~~^^^^^^^^^^^^^^^^^^^^^^^^^^^^
  File "/usr/local/lib/python3.13/site-packages/django/db/models/query.py", line 91, in __iter__
    results = compiler.execute_sql(
        chunked_fetch=self.chunked_fetch, chunk_size=self.chunk_size
    )
  File "/usr/local/lib/python3.13/site-packages/django/db/models/sql/compiler.py", line 1574, in execute_sql
    cursor.execute(sql, params)
    ~~~~~~~~~~~~~~^^^^^^^^^^^^^
  File "/usr/local/lib/python3.13/site-packages/django/db/backends/utils.py", line 122, in execute
    return super().execute(sql, params)
           ~~~~~~~~~~~~~~~^^^^^^^^^^^^^
  File "/usr/local/lib/python3.13/site-packages/django/db/backends/utils.py", line 79, in execute
    return self._execute_with_wrappers(
           ~~~~~~~~~~~~~~~~~~~~~~~~~~~^
        sql, params, many=False, executor=self._execute
        ^^^^^^^^^^^^^^^^^^^^^^^^^^^^^^^^^^^^^^^^^^^^^^^
    )
    ^
  File "/usr/local/lib/python3.13/site-packages/django/db/backends/utils.py", line 92, in _execute_with_wrappers
    return executor(sql, params, many, context)
  File "/usr/local/lib/python3.13/site-packages/django/db/backends/utils.py", line 100, in _execute
    with self.db.wrap_database_errors:
         ^^^^^^^^^^^^^^^^^^^^^^^^^^^^
  File "/usr/local/lib/python3.13/site-packages/django/db/utils.py", line 91, in __exit__
    raise dj_exc_value.with_traceback(traceback) from exc_value
  File "/usr/local/lib/python3.13/site-packages/django/db/backends/utils.py", line 105, in _execute
    return self.cursor.execute(sql, params)
           ~~~~~~~~~~~~~~~~~~~^^^^^^^^^^^^^
  File "/usr/local/lib/python3.13/site-packages/django/db/backends/sqlite3/base.py", line 354, in execute
    return super().execute(query, params)
           ~~~~~~~~~~~~~~~^^^^^^^^^^^^^^^
django.db.utils.OperationalError: no such table: common_userprofile
ERROR 2024-12-08 14:37:29,561 basehttp "GET /common/currentuser/ HTTP/1.1" 500 158902
ERROR 2024-12-08 14:41:22,512 log Internal Server Error: /common/currentuser/
Traceback (most recent call last):
  File "/usr/local/lib/python3.13/site-packages/django/core/handlers/exception.py", line 55, in inner
    response = get_response(request)
  File "/usr/local/lib/python3.13/site-packages/django/core/handlers/base.py", line 197, in _get_response
    response = wrapped_callback(request, *callback_args, **callback_kwargs)
  File "/usr/local/lib/python3.13/site-packages/django/views/decorators/csrf.py", line 65, in _view_wrapper
    return view_func(request, *args, **kwargs)
  File "/usr/local/lib/python3.13/site-packages/django/views/generic/base.py", line 104, in view
    return self.dispatch(request, *args, **kwargs)
           ~~~~~~~~~~~~~^^^^^^^^^^^^^^^^^^^^^^^^^^
  File "/usr/local/lib/python3.13/site-packages/rest_framework/views.py", line 509, in dispatch
    response = self.handle_exception(exc)
  File "/usr/local/lib/python3.13/site-packages/rest_framework/views.py", line 469, in handle_exception
    self.raise_uncaught_exception(exc)
    ~~~~~~~~~~~~~~~~~~~~~~~~~~~~~^^^^^
  File "/usr/local/lib/python3.13/site-packages/rest_framework/views.py", line 480, in raise_uncaught_exception
    raise exc
  File "/usr/local/lib/python3.13/site-packages/rest_framework/views.py", line 506, in dispatch
    response = handler(request, *args, **kwargs)
  File "/app/common/views.py", line 89, in get
    userprofile = UserProfile.objects.get(user=user)
  File "/usr/local/lib/python3.13/site-packages/django/db/models/manager.py", line 87, in manager_method
    return getattr(self.get_queryset(), name)(*args, **kwargs)
           ~~~~~~~~~~~~~~~~~~~~~~~~~~~~~~~~~~^^^^^^^^^^^^^^^^^
  File "/usr/local/lib/python3.13/site-packages/django/db/models/query.py", line 649, in get
    raise self.model.DoesNotExist(
        "%s matching query does not exist." % self.model._meta.object_name
    )
common.models.UserProfile.DoesNotExist: UserProfile matching query does not exist.
ERROR 2024-12-08 14:41:22,521 basehttp "GET /common/currentuser/ HTTP/1.1" 500 95061
ERROR 2024-12-08 14:45:28,111 log Internal Server Error: /common/currentuser/
Traceback (most recent call last):
  File "/usr/local/lib/python3.13/site-packages/django/core/handlers/exception.py", line 55, in inner
    response = get_response(request)
  File "/usr/local/lib/python3.13/site-packages/django/core/handlers/base.py", line 197, in _get_response
    response = wrapped_callback(request, *callback_args, **callback_kwargs)
  File "/usr/local/lib/python3.13/site-packages/django/views/decorators/csrf.py", line 65, in _view_wrapper
    return view_func(request, *args, **kwargs)
  File "/usr/local/lib/python3.13/site-packages/django/views/generic/base.py", line 104, in view
    return self.dispatch(request, *args, **kwargs)
           ~~~~~~~~~~~~~^^^^^^^^^^^^^^^^^^^^^^^^^^
  File "/usr/local/lib/python3.13/site-packages/rest_framework/views.py", line 509, in dispatch
    response = self.handle_exception(exc)
  File "/usr/local/lib/python3.13/site-packages/rest_framework/views.py", line 469, in handle_exception
    self.raise_uncaught_exception(exc)
    ~~~~~~~~~~~~~~~~~~~~~~~~~~~~~^^^^^
  File "/usr/local/lib/python3.13/site-packages/rest_framework/views.py", line 480, in raise_uncaught_exception
    raise exc
  File "/usr/local/lib/python3.13/site-packages/rest_framework/views.py", line 506, in dispatch
    response = handler(request, *args, **kwargs)
  File "/app/common/views.py", line 89, in get
    userprofile = UserProfile.objects.get(user=user)
  File "/usr/local/lib/python3.13/site-packages/django/db/models/manager.py", line 87, in manager_method
    return getattr(self.get_queryset(), name)(*args, **kwargs)
           ~~~~~~~~~~~~~~~~~~~~~~~~~~~~~~~~~~^^^^^^^^^^^^^^^^^
  File "/usr/local/lib/python3.13/site-packages/django/db/models/query.py", line 649, in get
    raise self.model.DoesNotExist(
        "%s matching query does not exist." % self.model._meta.object_name
    )
common.models.UserProfile.DoesNotExist: UserProfile matching query does not exist.
ERROR 2024-12-08 14:45:28,134 basehttp "GET /common/currentuser/ HTTP/1.1" 500 95061
ERROR 2024-12-14 05:59:55,799 log Internal Server Error: /api/products/
Traceback (most recent call last):
  File "/usr/local/lib/python3.13/site-packages/django/db/backends/utils.py", line 105, in _execute
    return self.cursor.execute(sql, params)
           ~~~~~~~~~~~~~~~~~~~^^^^^^^^^^^^^
  File "/usr/local/lib/python3.13/site-packages/django/db/backends/sqlite3/base.py", line 354, in execute
    return super().execute(query, params)
           ~~~~~~~~~~~~~~~^^^^^^^^^^^^^^^
sqlite3.OperationalError: no such table: products_product

The above exception was the direct cause of the following exception:

Traceback (most recent call last):
  File "/usr/local/lib/python3.13/site-packages/django/core/handlers/exception.py", line 55, in inner
    response = get_response(request)
  File "/usr/local/lib/python3.13/site-packages/django/core/handlers/base.py", line 197, in _get_response
    response = wrapped_callback(request, *callback_args, **callback_kwargs)
  File "/usr/local/lib/python3.13/site-packages/django/views/decorators/csrf.py", line 65, in _view_wrapper
    return view_func(request, *args, **kwargs)
  File "/usr/local/lib/python3.13/site-packages/django/views/generic/base.py", line 104, in view
    return self.dispatch(request, *args, **kwargs)
           ~~~~~~~~~~~~~^^^^^^^^^^^^^^^^^^^^^^^^^^
  File "/usr/local/lib/python3.13/site-packages/rest_framework/views.py", line 509, in dispatch
    response = self.handle_exception(exc)
  File "/usr/local/lib/python3.13/site-packages/rest_framework/views.py", line 469, in handle_exception
    self.raise_uncaught_exception(exc)
    ~~~~~~~~~~~~~~~~~~~~~~~~~~~~~^^^^^
  File "/usr/local/lib/python3.13/site-packages/rest_framework/views.py", line 480, in raise_uncaught_exception
    raise exc
  File "/usr/local/lib/python3.13/site-packages/rest_framework/views.py", line 506, in dispatch
    response = handler(request, *args, **kwargs)
  File "/app/products/views.py", line 49, in get
    if not products.exists():
           ~~~~~~~~~~~~~~~^^
  File "/usr/local/lib/python3.13/site-packages/django/db/models/query.py", line 1288, in exists
    return self.query.has_results(using=self.db)
           ~~~~~~~~~~~~~~~~~~~~~~^^^^^^^^^^^^^^^
  File "/usr/local/lib/python3.13/site-packages/django/db/models/sql/query.py", line 660, in has_results
    return compiler.has_results()
           ~~~~~~~~~~~~~~~~~~~~^^
  File "/usr/local/lib/python3.13/site-packages/django/db/models/sql/compiler.py", line 1542, in has_results
    return bool(self.execute_sql(SINGLE))
                ~~~~~~~~~~~~~~~~^^^^^^^^
  File "/usr/local/lib/python3.13/site-packages/django/db/models/sql/compiler.py", line 1574, in execute_sql
    cursor.execute(sql, params)
    ~~~~~~~~~~~~~~^^^^^^^^^^^^^
  File "/usr/local/lib/python3.13/site-packages/django/db/backends/utils.py", line 122, in execute
    return super().execute(sql, params)
           ~~~~~~~~~~~~~~~^^^^^^^^^^^^^
  File "/usr/local/lib/python3.13/site-packages/django/db/backends/utils.py", line 79, in execute
    return self._execute_with_wrappers(
           ~~~~~~~~~~~~~~~~~~~~~~~~~~~^
        sql, params, many=False, executor=self._execute
        ^^^^^^^^^^^^^^^^^^^^^^^^^^^^^^^^^^^^^^^^^^^^^^^
    )
    ^
  File "/usr/local/lib/python3.13/site-packages/django/db/backends/utils.py", line 92, in _execute_with_wrappers
    return executor(sql, params, many, context)
  File "/usr/local/lib/python3.13/site-packages/django/db/backends/utils.py", line 100, in _execute
    with self.db.wrap_database_errors:
         ^^^^^^^^^^^^^^^^^^^^^^^^^^^^
  File "/usr/local/lib/python3.13/site-packages/django/db/utils.py", line 91, in __exit__
    raise dj_exc_value.with_traceback(traceback) from exc_value
  File "/usr/local/lib/python3.13/site-packages/django/db/backends/utils.py", line 105, in _execute
    return self.cursor.execute(sql, params)
           ~~~~~~~~~~~~~~~~~~~^^^^^^^^^^^^^
  File "/usr/local/lib/python3.13/site-packages/django/db/backends/sqlite3/base.py", line 354, in execute
    return super().execute(query, params)
           ~~~~~~~~~~~~~~~^^^^^^^^^^^^^^^
django.db.utils.OperationalError: no such table: products_product
ERROR 2024-12-14 05:59:55,809 basehttp "GET /api/products/ HTTP/1.1" 500 146281
ERROR 2024-12-14 06:04:36,784 log Internal Server Error: /api/products/
Traceback (most recent call last):
  File "/usr/local/lib/python3.13/site-packages/django/db/backends/utils.py", line 105, in _execute
    return self.cursor.execute(sql, params)
           ~~~~~~~~~~~~~~~~~~~^^^^^^^^^^^^^
  File "/usr/local/lib/python3.13/site-packages/django/db/backends/sqlite3/base.py", line 354, in execute
    return super().execute(query, params)
           ~~~~~~~~~~~~~~~^^^^^^^^^^^^^^^
sqlite3.OperationalError: no such table: products_category

The above exception was the direct cause of the following exception:

Traceback (most recent call last):
  File "/usr/local/lib/python3.13/site-packages/django/core/handlers/exception.py", line 55, in inner
    response = get_response(request)
  File "/usr/local/lib/python3.13/site-packages/django/core/handlers/base.py", line 197, in _get_response
    response = wrapped_callback(request, *callback_args, **callback_kwargs)
  File "/usr/local/lib/python3.13/site-packages/django/views/decorators/csrf.py", line 65, in _view_wrapper
    return view_func(request, *args, **kwargs)
  File "/usr/local/lib/python3.13/site-packages/django/views/generic/base.py", line 104, in view
    return self.dispatch(request, *args, **kwargs)
           ~~~~~~~~~~~~~^^^^^^^^^^^^^^^^^^^^^^^^^^
  File "/usr/local/lib/python3.13/site-packages/rest_framework/views.py", line 509, in dispatch
    response = self.handle_exception(exc)
  File "/usr/local/lib/python3.13/site-packages/rest_framework/views.py", line 469, in handle_exception
    self.raise_uncaught_exception(exc)
    ~~~~~~~~~~~~~~~~~~~~~~~~~~~~~^^^^^
  File "/usr/local/lib/python3.13/site-packages/rest_framework/views.py", line 480, in raise_uncaught_exception
    raise exc
  File "/usr/local/lib/python3.13/site-packages/rest_framework/views.py", line 506, in dispatch
    response = handler(request, *args, **kwargs)
  File "/app/products/views.py", line 61, in post
    if serializer.is_valid():
       ~~~~~~~~~~~~~~~~~~~^^
  File "/usr/local/lib/python3.13/site-packages/rest_framework/serializers.py", line 223, in is_valid
    self._validated_data = self.run_validation(self.initial_data)
                           ~~~~~~~~~~~~~~~~~~~^^^^^^^^^^^^^^^^^^^
  File "/usr/local/lib/python3.13/site-packages/rest_framework/serializers.py", line 442, in run_validation
    value = self.to_internal_value(data)
  File "/usr/local/lib/python3.13/site-packages/rest_framework/serializers.py", line 499, in to_internal_value
    validated_value = field.run_validation(primitive_value)
  File "/usr/local/lib/python3.13/site-packages/rest_framework/relations.py", line 155, in run_validation
    return super().run_validation(data)
           ~~~~~~~~~~~~~~~~~~~~~~^^^^^^
  File "/usr/local/lib/python3.13/site-packages/rest_framework/fields.py", line 538, in run_validation
    value = self.to_internal_value(data)
  File "/usr/local/lib/python3.13/site-packages/rest_framework/relations.py", line 259, in to_internal_value
    return queryset.get(pk=data)
           ~~~~~~~~~~~~^^^^^^^^^
  File "/usr/local/lib/python3.13/site-packages/django/db/models/query.py", line 645, in get
    num = len(clone)
  File "/usr/local/lib/python3.13/site-packages/django/db/models/query.py", line 382, in __len__
    self._fetch_all()
    ~~~~~~~~~~~~~~~^^
  File "/usr/local/lib/python3.13/site-packages/django/db/models/query.py", line 1928, in _fetch_all
    self._result_cache = list(self._iterable_class(self))
                         ~~~~^^^^^^^^^^^^^^^^^^^^^^^^^^^^
  File "/usr/local/lib/python3.13/site-packages/django/db/models/query.py", line 91, in __iter__
    results = compiler.execute_sql(
        chunked_fetch=self.chunked_fetch, chunk_size=self.chunk_size
    )
  File "/usr/local/lib/python3.13/site-packages/django/db/models/sql/compiler.py", line 1574, in execute_sql
    cursor.execute(sql, params)
    ~~~~~~~~~~~~~~^^^^^^^^^^^^^
  File "/usr/local/lib/python3.13/site-packages/django/db/backends/utils.py", line 122, in execute
    return super().execute(sql, params)
           ~~~~~~~~~~~~~~~^^^^^^^^^^^^^
  File "/usr/local/lib/python3.13/site-packages/django/db/backends/utils.py", line 79, in execute
    return self._execute_with_wrappers(
           ~~~~~~~~~~~~~~~~~~~~~~~~~~~^
        sql, params, many=False, executor=self._execute
        ^^^^^^^^^^^^^^^^^^^^^^^^^^^^^^^^^^^^^^^^^^^^^^^
    )
    ^
  File "/usr/local/lib/python3.13/site-packages/django/db/backends/utils.py", line 92, in _execute_with_wrappers
    return executor(sql, params, many, context)
  File "/usr/local/lib/python3.13/site-packages/django/db/backends/utils.py", line 100, in _execute
    with self.db.wrap_database_errors:
         ^^^^^^^^^^^^^^^^^^^^^^^^^^^^
  File "/usr/local/lib/python3.13/site-packages/django/db/utils.py", line 91, in __exit__
    raise dj_exc_value.with_traceback(traceback) from exc_value
  File "/usr/local/lib/python3.13/site-packages/django/db/backends/utils.py", line 105, in _execute
    return self.cursor.execute(sql, params)
           ~~~~~~~~~~~~~~~~~~~^^^^^^^^^^^^^
  File "/usr/local/lib/python3.13/site-packages/django/db/backends/sqlite3/base.py", line 354, in execute
    return super().execute(query, params)
           ~~~~~~~~~~~~~~~^^^^^^^^^^^^^^^
django.db.utils.OperationalError: no such table: products_category
ERROR 2024-12-14 06:04:36,789 basehttp "POST /api/products/ HTTP/1.1" 500 180842
ERROR 2024-12-14 06:37:08,168 log Internal Server Error: /admin/login/
Traceback (most recent call last):
  File "/usr/local/lib/python3.13/site-packages/django/db/backends/utils.py", line 105, in _execute
    return self.cursor.execute(sql, params)
           ~~~~~~~~~~~~~~~~~~~^^^^^^^^^^^^^
  File "/usr/local/lib/python3.13/site-packages/django/db/backends/sqlite3/base.py", line 354, in execute
    return super().execute(query, params)
           ~~~~~~~~~~~~~~~^^^^^^^^^^^^^^^
sqlite3.OperationalError: no such table: django_session

The above exception was the direct cause of the following exception:

Traceback (most recent call last):
  File "/usr/local/lib/python3.13/site-packages/django/core/handlers/exception.py", line 55, in inner
    response = get_response(request)
  File "/usr/local/lib/python3.13/site-packages/django/core/handlers/base.py", line 197, in _get_response
    response = wrapped_callback(request, *callback_args, **callback_kwargs)
  File "/usr/local/lib/python3.13/site-packages/django/utils/decorators.py", line 48, in _wrapper
    return bound_method(*args, **kwargs)
  File "/usr/local/lib/python3.13/site-packages/django/views/decorators/cache.py", line 80, in _view_wrapper
    response = view_func(request, *args, **kwargs)
  File "/usr/local/lib/python3.13/site-packages/django/contrib/admin/sites.py", line 444, in login
    return LoginView.as_view(**defaults)(request)
           ~~~~~~~~~~~~~~~~~~~~~~~~~~~~~^^^^^^^^^
  File "/usr/local/lib/python3.13/site-packages/django/views/generic/base.py", line 104, in view
    return self.dispatch(request, *args, **kwargs)
           ~~~~~~~~~~~~~^^^^^^^^^^^^^^^^^^^^^^^^^^
  File "/usr/local/lib/python3.13/site-packages/django/utils/decorators.py", line 48, in _wrapper
    return bound_method(*args, **kwargs)
  File "/usr/local/lib/python3.13/site-packages/django/utils/decorators.py", line 48, in _wrapper
    return bound_method(*args, **kwargs)
  File "/usr/local/lib/python3.13/site-packages/django/views/decorators/debug.py", line 143, in sensitive_post_parameters_wrapper
    return view(request, *args, **kwargs)
  File "/usr/local/lib/python3.13/site-packages/django/utils/decorators.py", line 48, in _wrapper
    return bound_method(*args, **kwargs)
  File "/usr/local/lib/python3.13/site-packages/django/utils/decorators.py", line 188, in _view_wrapper
    result = _process_exception(request, e)
  File "/usr/local/lib/python3.13/site-packages/django/utils/decorators.py", line 186, in _view_wrapper
    response = view_func(request, *args, **kwargs)
  File "/usr/local/lib/python3.13/site-packages/django/utils/decorators.py", line 48, in _wrapper
    return bound_method(*args, **kwargs)
  File "/usr/local/lib/python3.13/site-packages/django/views/decorators/cache.py", line 80, in _view_wrapper
    response = view_func(request, *args, **kwargs)
  File "/usr/local/lib/python3.13/site-packages/django/contrib/auth/views.py", line 89, in dispatch
    return super().dispatch(request, *args, **kwargs)
           ~~~~~~~~~~~~~~~~^^^^^^^^^^^^^^^^^^^^^^^^^^
  File "/usr/local/lib/python3.13/site-packages/django/views/generic/base.py", line 143, in dispatch
    return handler(request, *args, **kwargs)
  File "/usr/local/lib/python3.13/site-packages/django/views/generic/edit.py", line 151, in post
    return self.form_valid(form)
           ~~~~~~~~~~~~~~~^^^^^^
  File "/usr/local/lib/python3.13/site-packages/django/contrib/auth/views.py", line 108, in form_valid
    auth_login(self.request, form.get_user())
    ~~~~~~~~~~^^^^^^^^^^^^^^^^^^^^^^^^^^^^^^^
  File "/usr/local/lib/python3.13/site-packages/django/contrib/auth/__init__.py", line 126, in login
    request.session.cycle_key()
    ~~~~~~~~~~~~~~~~~~~~~~~~~^^
  File "/usr/local/lib/python3.13/site-packages/django/contrib/sessions/backends/base.py", line 432, in cycle_key
    self.create()
    ~~~~~~~~~~~^^
  File "/usr/local/lib/python3.13/site-packages/django/contrib/sessions/backends/db.py", line 70, in create
    self._session_key = self._get_new_session_key()
                        ~~~~~~~~~~~~~~~~~~~~~~~~~^^
  File "/usr/local/lib/python3.13/site-packages/django/contrib/sessions/backends/base.py", line 196, in _get_new_session_key
    if not self.exists(session_key):
           ~~~~~~~~~~~^^^^^^^^^^^^^
  File "/usr/local/lib/python3.13/site-packages/django/contrib/sessions/backends/db.py", line 63, in exists
    return self.model.objects.filter(session_key=session_key).exists()
           ~~~~~~~~~~~~~~~~~~~~~~~~~~~~~~~~~~~~~~~~~~~~~~~~~~~~~~~~~^^
  File "/usr/local/lib/python3.13/site-packages/django/db/models/query.py", line 1288, in exists
    return self.query.has_results(using=self.db)
           ~~~~~~~~~~~~~~~~~~~~~~^^^^^^^^^^^^^^^
  File "/usr/local/lib/python3.13/site-packages/django/db/models/sql/query.py", line 660, in has_results
    return compiler.has_results()
           ~~~~~~~~~~~~~~~~~~~~^^
  File "/usr/local/lib/python3.13/site-packages/django/db/models/sql/compiler.py", line 1542, in has_results
    return bool(self.execute_sql(SINGLE))
                ~~~~~~~~~~~~~~~~^^^^^^^^
  File "/usr/local/lib/python3.13/site-packages/django/db/models/sql/compiler.py", line 1574, in execute_sql
    cursor.execute(sql, params)
    ~~~~~~~~~~~~~~^^^^^^^^^^^^^
  File "/usr/local/lib/python3.13/site-packages/django/db/backends/utils.py", line 122, in execute
    return super().execute(sql, params)
           ~~~~~~~~~~~~~~~^^^^^^^^^^^^^
  File "/usr/local/lib/python3.13/site-packages/django/db/backends/utils.py", line 79, in execute
    return self._execute_with_wrappers(
           ~~~~~~~~~~~~~~~~~~~~~~~~~~~^
        sql, params, many=False, executor=self._execute
        ^^^^^^^^^^^^^^^^^^^^^^^^^^^^^^^^^^^^^^^^^^^^^^^
    )
    ^
  File "/usr/local/lib/python3.13/site-packages/django/db/backends/utils.py", line 92, in _execute_with_wrappers
    return executor(sql, params, many, context)
  File "/usr/local/lib/python3.13/site-packages/django/db/backends/utils.py", line 100, in _execute
    with self.db.wrap_database_errors:
         ^^^^^^^^^^^^^^^^^^^^^^^^^^^^
  File "/usr/local/lib/python3.13/site-packages/django/db/utils.py", line 91, in __exit__
    raise dj_exc_value.with_traceback(traceback) from exc_value
  File "/usr/local/lib/python3.13/site-packages/django/db/backends/utils.py", line 105, in _execute
    return self.cursor.execute(sql, params)
           ~~~~~~~~~~~~~~~~~~~^^^^^^^^^^^^^
  File "/usr/local/lib/python3.13/site-packages/django/db/backends/sqlite3/base.py", line 354, in execute
    return super().execute(query, params)
           ~~~~~~~~~~~~~~~^^^^^^^^^^^^^^^
django.db.utils.OperationalError: no such table: django_session
ERROR 2024-12-14 06:37:08,185 basehttp "POST /admin/login/?next=/admin/ HTTP/1.1" 500 215846
ERROR 2024-12-14 06:45:04,922 log Internal Server Error: /admin/login/
Traceback (most recent call last):
  File "/usr/local/lib/python3.13/site-packages/django/db/backends/utils.py", line 105, in _execute
    return self.cursor.execute(sql, params)
           ~~~~~~~~~~~~~~~~~~~^^^^^^^^^^^^^
  File "/usr/local/lib/python3.13/site-packages/django/db/backends/sqlite3/base.py", line 354, in execute
    return super().execute(query, params)
           ~~~~~~~~~~~~~~~^^^^^^^^^^^^^^^
sqlite3.OperationalError: no such table: django_session

The above exception was the direct cause of the following exception:

Traceback (most recent call last):
  File "/usr/local/lib/python3.13/site-packages/django/core/handlers/exception.py", line 55, in inner
    response = get_response(request)
  File "/usr/local/lib/python3.13/site-packages/django/core/handlers/base.py", line 197, in _get_response
    response = wrapped_callback(request, *callback_args, **callback_kwargs)
  File "/usr/local/lib/python3.13/site-packages/django/utils/decorators.py", line 48, in _wrapper
    return bound_method(*args, **kwargs)
  File "/usr/local/lib/python3.13/site-packages/django/views/decorators/cache.py", line 80, in _view_wrapper
    response = view_func(request, *args, **kwargs)
  File "/usr/local/lib/python3.13/site-packages/django/contrib/admin/sites.py", line 444, in login
    return LoginView.as_view(**defaults)(request)
           ~~~~~~~~~~~~~~~~~~~~~~~~~~~~~^^^^^^^^^
  File "/usr/local/lib/python3.13/site-packages/django/views/generic/base.py", line 104, in view
    return self.dispatch(request, *args, **kwargs)
           ~~~~~~~~~~~~~^^^^^^^^^^^^^^^^^^^^^^^^^^
  File "/usr/local/lib/python3.13/site-packages/django/utils/decorators.py", line 48, in _wrapper
    return bound_method(*args, **kwargs)
  File "/usr/local/lib/python3.13/site-packages/django/utils/decorators.py", line 48, in _wrapper
    return bound_method(*args, **kwargs)
  File "/usr/local/lib/python3.13/site-packages/django/views/decorators/debug.py", line 143, in sensitive_post_parameters_wrapper
    return view(request, *args, **kwargs)
  File "/usr/local/lib/python3.13/site-packages/django/utils/decorators.py", line 48, in _wrapper
    return bound_method(*args, **kwargs)
  File "/usr/local/lib/python3.13/site-packages/django/utils/decorators.py", line 188, in _view_wrapper
    result = _process_exception(request, e)
  File "/usr/local/lib/python3.13/site-packages/django/utils/decorators.py", line 186, in _view_wrapper
    response = view_func(request, *args, **kwargs)
  File "/usr/local/lib/python3.13/site-packages/django/utils/decorators.py", line 48, in _wrapper
    return bound_method(*args, **kwargs)
  File "/usr/local/lib/python3.13/site-packages/django/views/decorators/cache.py", line 80, in _view_wrapper
    response = view_func(request, *args, **kwargs)
  File "/usr/local/lib/python3.13/site-packages/django/contrib/auth/views.py", line 89, in dispatch
    return super().dispatch(request, *args, **kwargs)
           ~~~~~~~~~~~~~~~~^^^^^^^^^^^^^^^^^^^^^^^^^^
  File "/usr/local/lib/python3.13/site-packages/django/views/generic/base.py", line 143, in dispatch
    return handler(request, *args, **kwargs)
  File "/usr/local/lib/python3.13/site-packages/django/views/generic/edit.py", line 151, in post
    return self.form_valid(form)
           ~~~~~~~~~~~~~~~^^^^^^
  File "/usr/local/lib/python3.13/site-packages/django/contrib/auth/views.py", line 108, in form_valid
    auth_login(self.request, form.get_user())
    ~~~~~~~~~~^^^^^^^^^^^^^^^^^^^^^^^^^^^^^^^
  File "/usr/local/lib/python3.13/site-packages/django/contrib/auth/__init__.py", line 126, in login
    request.session.cycle_key()
    ~~~~~~~~~~~~~~~~~~~~~~~~~^^
  File "/usr/local/lib/python3.13/site-packages/django/contrib/sessions/backends/base.py", line 432, in cycle_key
    self.create()
    ~~~~~~~~~~~^^
  File "/usr/local/lib/python3.13/site-packages/django/contrib/sessions/backends/db.py", line 70, in create
    self._session_key = self._get_new_session_key()
                        ~~~~~~~~~~~~~~~~~~~~~~~~~^^
  File "/usr/local/lib/python3.13/site-packages/django/contrib/sessions/backends/base.py", line 196, in _get_new_session_key
    if not self.exists(session_key):
           ~~~~~~~~~~~^^^^^^^^^^^^^
  File "/usr/local/lib/python3.13/site-packages/django/contrib/sessions/backends/db.py", line 63, in exists
    return self.model.objects.filter(session_key=session_key).exists()
           ~~~~~~~~~~~~~~~~~~~~~~~~~~~~~~~~~~~~~~~~~~~~~~~~~~~~~~~~~^^
  File "/usr/local/lib/python3.13/site-packages/django/db/models/query.py", line 1288, in exists
    return self.query.has_results(using=self.db)
           ~~~~~~~~~~~~~~~~~~~~~~^^^^^^^^^^^^^^^
  File "/usr/local/lib/python3.13/site-packages/django/db/models/sql/query.py", line 660, in has_results
    return compiler.has_results()
           ~~~~~~~~~~~~~~~~~~~~^^
  File "/usr/local/lib/python3.13/site-packages/django/db/models/sql/compiler.py", line 1542, in has_results
    return bool(self.execute_sql(SINGLE))
                ~~~~~~~~~~~~~~~~^^^^^^^^
  File "/usr/local/lib/python3.13/site-packages/django/db/models/sql/compiler.py", line 1574, in execute_sql
    cursor.execute(sql, params)
    ~~~~~~~~~~~~~~^^^^^^^^^^^^^
  File "/usr/local/lib/python3.13/site-packages/django/db/backends/utils.py", line 122, in execute
    return super().execute(sql, params)
           ~~~~~~~~~~~~~~~^^^^^^^^^^^^^
  File "/usr/local/lib/python3.13/site-packages/django/db/backends/utils.py", line 79, in execute
    return self._execute_with_wrappers(
           ~~~~~~~~~~~~~~~~~~~~~~~~~~~^
        sql, params, many=False, executor=self._execute
        ^^^^^^^^^^^^^^^^^^^^^^^^^^^^^^^^^^^^^^^^^^^^^^^
    )
    ^
  File "/usr/local/lib/python3.13/site-packages/django/db/backends/utils.py", line 92, in _execute_with_wrappers
    return executor(sql, params, many, context)
  File "/usr/local/lib/python3.13/site-packages/django/db/backends/utils.py", line 100, in _execute
    with self.db.wrap_database_errors:
         ^^^^^^^^^^^^^^^^^^^^^^^^^^^^
  File "/usr/local/lib/python3.13/site-packages/django/db/utils.py", line 91, in __exit__
    raise dj_exc_value.with_traceback(traceback) from exc_value
  File "/usr/local/lib/python3.13/site-packages/django/db/backends/utils.py", line 105, in _execute
    return self.cursor.execute(sql, params)
           ~~~~~~~~~~~~~~~~~~~^^^^^^^^^^^^^
  File "/usr/local/lib/python3.13/site-packages/django/db/backends/sqlite3/base.py", line 354, in execute
    return super().execute(query, params)
           ~~~~~~~~~~~~~~~^^^^^^^^^^^^^^^
django.db.utils.OperationalError: no such table: django_session
ERROR 2024-12-14 06:45:04,934 basehttp "POST /admin/login/?next=/admin/ HTTP/1.1" 500 215846
ERROR 2024-12-14 06:45:32,029 log Internal Server Error: /admin/login/
Traceback (most recent call last):
  File "/usr/local/lib/python3.13/site-packages/django/db/backends/utils.py", line 105, in _execute
    return self.cursor.execute(sql, params)
           ~~~~~~~~~~~~~~~~~~~^^^^^^^^^^^^^
  File "/usr/local/lib/python3.13/site-packages/django/db/backends/sqlite3/base.py", line 354, in execute
    return super().execute(query, params)
           ~~~~~~~~~~~~~~~^^^^^^^^^^^^^^^
sqlite3.OperationalError: no such table: django_session

The above exception was the direct cause of the following exception:

Traceback (most recent call last):
  File "/usr/local/lib/python3.13/site-packages/django/core/handlers/exception.py", line 55, in inner
    response = get_response(request)
  File "/usr/local/lib/python3.13/site-packages/django/core/handlers/base.py", line 197, in _get_response
    response = wrapped_callback(request, *callback_args, **callback_kwargs)
  File "/usr/local/lib/python3.13/site-packages/django/utils/decorators.py", line 48, in _wrapper
    return bound_method(*args, **kwargs)
  File "/usr/local/lib/python3.13/site-packages/django/views/decorators/cache.py", line 80, in _view_wrapper
    response = view_func(request, *args, **kwargs)
  File "/usr/local/lib/python3.13/site-packages/django/contrib/admin/sites.py", line 444, in login
    return LoginView.as_view(**defaults)(request)
           ~~~~~~~~~~~~~~~~~~~~~~~~~~~~~^^^^^^^^^
  File "/usr/local/lib/python3.13/site-packages/django/views/generic/base.py", line 104, in view
    return self.dispatch(request, *args, **kwargs)
           ~~~~~~~~~~~~~^^^^^^^^^^^^^^^^^^^^^^^^^^
  File "/usr/local/lib/python3.13/site-packages/django/utils/decorators.py", line 48, in _wrapper
    return bound_method(*args, **kwargs)
  File "/usr/local/lib/python3.13/site-packages/django/utils/decorators.py", line 48, in _wrapper
    return bound_method(*args, **kwargs)
  File "/usr/local/lib/python3.13/site-packages/django/views/decorators/debug.py", line 143, in sensitive_post_parameters_wrapper
    return view(request, *args, **kwargs)
  File "/usr/local/lib/python3.13/site-packages/django/utils/decorators.py", line 48, in _wrapper
    return bound_method(*args, **kwargs)
  File "/usr/local/lib/python3.13/site-packages/django/utils/decorators.py", line 188, in _view_wrapper
    result = _process_exception(request, e)
  File "/usr/local/lib/python3.13/site-packages/django/utils/decorators.py", line 186, in _view_wrapper
    response = view_func(request, *args, **kwargs)
  File "/usr/local/lib/python3.13/site-packages/django/utils/decorators.py", line 48, in _wrapper
    return bound_method(*args, **kwargs)
  File "/usr/local/lib/python3.13/site-packages/django/views/decorators/cache.py", line 80, in _view_wrapper
    response = view_func(request, *args, **kwargs)
  File "/usr/local/lib/python3.13/site-packages/django/contrib/auth/views.py", line 89, in dispatch
    return super().dispatch(request, *args, **kwargs)
           ~~~~~~~~~~~~~~~~^^^^^^^^^^^^^^^^^^^^^^^^^^
  File "/usr/local/lib/python3.13/site-packages/django/views/generic/base.py", line 143, in dispatch
    return handler(request, *args, **kwargs)
  File "/usr/local/lib/python3.13/site-packages/django/views/generic/edit.py", line 151, in post
    return self.form_valid(form)
           ~~~~~~~~~~~~~~~^^^^^^
  File "/usr/local/lib/python3.13/site-packages/django/contrib/auth/views.py", line 108, in form_valid
    auth_login(self.request, form.get_user())
    ~~~~~~~~~~^^^^^^^^^^^^^^^^^^^^^^^^^^^^^^^
  File "/usr/local/lib/python3.13/site-packages/django/contrib/auth/__init__.py", line 126, in login
    request.session.cycle_key()
    ~~~~~~~~~~~~~~~~~~~~~~~~~^^
  File "/usr/local/lib/python3.13/site-packages/django/contrib/sessions/backends/base.py", line 432, in cycle_key
    self.create()
    ~~~~~~~~~~~^^
  File "/usr/local/lib/python3.13/site-packages/django/contrib/sessions/backends/db.py", line 70, in create
    self._session_key = self._get_new_session_key()
                        ~~~~~~~~~~~~~~~~~~~~~~~~~^^
  File "/usr/local/lib/python3.13/site-packages/django/contrib/sessions/backends/base.py", line 196, in _get_new_session_key
    if not self.exists(session_key):
           ~~~~~~~~~~~^^^^^^^^^^^^^
  File "/usr/local/lib/python3.13/site-packages/django/contrib/sessions/backends/db.py", line 63, in exists
    return self.model.objects.filter(session_key=session_key).exists()
           ~~~~~~~~~~~~~~~~~~~~~~~~~~~~~~~~~~~~~~~~~~~~~~~~~~~~~~~~~^^
  File "/usr/local/lib/python3.13/site-packages/django/db/models/query.py", line 1288, in exists
    return self.query.has_results(using=self.db)
           ~~~~~~~~~~~~~~~~~~~~~~^^^^^^^^^^^^^^^
  File "/usr/local/lib/python3.13/site-packages/django/db/models/sql/query.py", line 660, in has_results
    return compiler.has_results()
           ~~~~~~~~~~~~~~~~~~~~^^
  File "/usr/local/lib/python3.13/site-packages/django/db/models/sql/compiler.py", line 1542, in has_results
    return bool(self.execute_sql(SINGLE))
                ~~~~~~~~~~~~~~~~^^^^^^^^
  File "/usr/local/lib/python3.13/site-packages/django/db/models/sql/compiler.py", line 1574, in execute_sql
    cursor.execute(sql, params)
    ~~~~~~~~~~~~~~^^^^^^^^^^^^^
  File "/usr/local/lib/python3.13/site-packages/django/db/backends/utils.py", line 122, in execute
    return super().execute(sql, params)
           ~~~~~~~~~~~~~~~^^^^^^^^^^^^^
  File "/usr/local/lib/python3.13/site-packages/django/db/backends/utils.py", line 79, in execute
    return self._execute_with_wrappers(
           ~~~~~~~~~~~~~~~~~~~~~~~~~~~^
        sql, params, many=False, executor=self._execute
        ^^^^^^^^^^^^^^^^^^^^^^^^^^^^^^^^^^^^^^^^^^^^^^^
    )
    ^
  File "/usr/local/lib/python3.13/site-packages/django/db/backends/utils.py", line 92, in _execute_with_wrappers
    return executor(sql, params, many, context)
  File "/usr/local/lib/python3.13/site-packages/django/db/backends/utils.py", line 100, in _execute
    with self.db.wrap_database_errors:
         ^^^^^^^^^^^^^^^^^^^^^^^^^^^^
  File "/usr/local/lib/python3.13/site-packages/django/db/utils.py", line 91, in __exit__
    raise dj_exc_value.with_traceback(traceback) from exc_value
  File "/usr/local/lib/python3.13/site-packages/django/db/backends/utils.py", line 105, in _execute
    return self.cursor.execute(sql, params)
           ~~~~~~~~~~~~~~~~~~~^^^^^^^^^^^^^
  File "/usr/local/lib/python3.13/site-packages/django/db/backends/sqlite3/base.py", line 354, in execute
    return super().execute(query, params)
           ~~~~~~~~~~~~~~~^^^^^^^^^^^^^^^
django.db.utils.OperationalError: no such table: django_session
ERROR 2024-12-14 06:45:32,036 basehttp "POST /admin/login/?next=/admin/ HTTP/1.1" 500 215846
ERROR 2024-12-14 06:49:31,835 log Internal Server Error: /admin/login/
Traceback (most recent call last):
  File "/usr/local/lib/python3.13/site-packages/django/db/backends/utils.py", line 105, in _execute
    return self.cursor.execute(sql, params)
           ~~~~~~~~~~~~~~~~~~~^^^^^^^^^^^^^
  File "/usr/local/lib/python3.13/site-packages/django/db/backends/sqlite3/base.py", line 354, in execute
    return super().execute(query, params)
           ~~~~~~~~~~~~~~~^^^^^^^^^^^^^^^
sqlite3.OperationalError: no such table: django_session

The above exception was the direct cause of the following exception:

Traceback (most recent call last):
  File "/usr/local/lib/python3.13/site-packages/django/core/handlers/exception.py", line 55, in inner
    response = get_response(request)
  File "/usr/local/lib/python3.13/site-packages/django/core/handlers/base.py", line 197, in _get_response
    response = wrapped_callback(request, *callback_args, **callback_kwargs)
  File "/usr/local/lib/python3.13/site-packages/django/utils/decorators.py", line 48, in _wrapper
    return bound_method(*args, **kwargs)
  File "/usr/local/lib/python3.13/site-packages/django/views/decorators/cache.py", line 80, in _view_wrapper
    response = view_func(request, *args, **kwargs)
  File "/usr/local/lib/python3.13/site-packages/django/contrib/admin/sites.py", line 444, in login
    return LoginView.as_view(**defaults)(request)
           ~~~~~~~~~~~~~~~~~~~~~~~~~~~~~^^^^^^^^^
  File "/usr/local/lib/python3.13/site-packages/django/views/generic/base.py", line 104, in view
    return self.dispatch(request, *args, **kwargs)
           ~~~~~~~~~~~~~^^^^^^^^^^^^^^^^^^^^^^^^^^
  File "/usr/local/lib/python3.13/site-packages/django/utils/decorators.py", line 48, in _wrapper
    return bound_method(*args, **kwargs)
  File "/usr/local/lib/python3.13/site-packages/django/utils/decorators.py", line 48, in _wrapper
    return bound_method(*args, **kwargs)
  File "/usr/local/lib/python3.13/site-packages/django/views/decorators/debug.py", line 143, in sensitive_post_parameters_wrapper
    return view(request, *args, **kwargs)
  File "/usr/local/lib/python3.13/site-packages/django/utils/decorators.py", line 48, in _wrapper
    return bound_method(*args, **kwargs)
  File "/usr/local/lib/python3.13/site-packages/django/utils/decorators.py", line 188, in _view_wrapper
    result = _process_exception(request, e)
  File "/usr/local/lib/python3.13/site-packages/django/utils/decorators.py", line 186, in _view_wrapper
    response = view_func(request, *args, **kwargs)
  File "/usr/local/lib/python3.13/site-packages/django/utils/decorators.py", line 48, in _wrapper
    return bound_method(*args, **kwargs)
  File "/usr/local/lib/python3.13/site-packages/django/views/decorators/cache.py", line 80, in _view_wrapper
    response = view_func(request, *args, **kwargs)
  File "/usr/local/lib/python3.13/site-packages/django/contrib/auth/views.py", line 89, in dispatch
    return super().dispatch(request, *args, **kwargs)
           ~~~~~~~~~~~~~~~~^^^^^^^^^^^^^^^^^^^^^^^^^^
  File "/usr/local/lib/python3.13/site-packages/django/views/generic/base.py", line 143, in dispatch
    return handler(request, *args, **kwargs)
  File "/usr/local/lib/python3.13/site-packages/django/views/generic/edit.py", line 151, in post
    return self.form_valid(form)
           ~~~~~~~~~~~~~~~^^^^^^
  File "/usr/local/lib/python3.13/site-packages/django/contrib/auth/views.py", line 108, in form_valid
    auth_login(self.request, form.get_user())
    ~~~~~~~~~~^^^^^^^^^^^^^^^^^^^^^^^^^^^^^^^
  File "/usr/local/lib/python3.13/site-packages/django/contrib/auth/__init__.py", line 126, in login
    request.session.cycle_key()
    ~~~~~~~~~~~~~~~~~~~~~~~~~^^
  File "/usr/local/lib/python3.13/site-packages/django/contrib/sessions/backends/base.py", line 432, in cycle_key
    self.create()
    ~~~~~~~~~~~^^
  File "/usr/local/lib/python3.13/site-packages/django/contrib/sessions/backends/db.py", line 70, in create
    self._session_key = self._get_new_session_key()
                        ~~~~~~~~~~~~~~~~~~~~~~~~~^^
  File "/usr/local/lib/python3.13/site-packages/django/contrib/sessions/backends/base.py", line 196, in _get_new_session_key
    if not self.exists(session_key):
           ~~~~~~~~~~~^^^^^^^^^^^^^
  File "/usr/local/lib/python3.13/site-packages/django/contrib/sessions/backends/db.py", line 63, in exists
    return self.model.objects.filter(session_key=session_key).exists()
           ~~~~~~~~~~~~~~~~~~~~~~~~~~~~~~~~~~~~~~~~~~~~~~~~~~~~~~~~~^^
  File "/usr/local/lib/python3.13/site-packages/django/db/models/query.py", line 1288, in exists
    return self.query.has_results(using=self.db)
           ~~~~~~~~~~~~~~~~~~~~~~^^^^^^^^^^^^^^^
  File "/usr/local/lib/python3.13/site-packages/django/db/models/sql/query.py", line 660, in has_results
    return compiler.has_results()
           ~~~~~~~~~~~~~~~~~~~~^^
  File "/usr/local/lib/python3.13/site-packages/django/db/models/sql/compiler.py", line 1542, in has_results
    return bool(self.execute_sql(SINGLE))
                ~~~~~~~~~~~~~~~~^^^^^^^^
  File "/usr/local/lib/python3.13/site-packages/django/db/models/sql/compiler.py", line 1574, in execute_sql
    cursor.execute(sql, params)
    ~~~~~~~~~~~~~~^^^^^^^^^^^^^
  File "/usr/local/lib/python3.13/site-packages/django/db/backends/utils.py", line 122, in execute
    return super().execute(sql, params)
           ~~~~~~~~~~~~~~~^^^^^^^^^^^^^
  File "/usr/local/lib/python3.13/site-packages/django/db/backends/utils.py", line 79, in execute
    return self._execute_with_wrappers(
           ~~~~~~~~~~~~~~~~~~~~~~~~~~~^
        sql, params, many=False, executor=self._execute
        ^^^^^^^^^^^^^^^^^^^^^^^^^^^^^^^^^^^^^^^^^^^^^^^
    )
    ^
  File "/usr/local/lib/python3.13/site-packages/django/db/backends/utils.py", line 92, in _execute_with_wrappers
    return executor(sql, params, many, context)
  File "/usr/local/lib/python3.13/site-packages/django/db/backends/utils.py", line 100, in _execute
    with self.db.wrap_database_errors:
         ^^^^^^^^^^^^^^^^^^^^^^^^^^^^
  File "/usr/local/lib/python3.13/site-packages/django/db/utils.py", line 91, in __exit__
    raise dj_exc_value.with_traceback(traceback) from exc_value
  File "/usr/local/lib/python3.13/site-packages/django/db/backends/utils.py", line 105, in _execute
    return self.cursor.execute(sql, params)
           ~~~~~~~~~~~~~~~~~~~^^^^^^^^^^^^^
  File "/usr/local/lib/python3.13/site-packages/django/db/backends/sqlite3/base.py", line 354, in execute
    return super().execute(query, params)
           ~~~~~~~~~~~~~~~^^^^^^^^^^^^^^^
django.db.utils.OperationalError: no such table: django_session
ERROR 2024-12-14 06:49:31,846 basehttp "POST /admin/login/?next=/admin/ HTTP/1.1" 500 215846
ERROR 2024-12-14 06:50:59,306 log Internal Server Error: /admin/products/category/add/
Traceback (most recent call last):
  File "/usr/local/lib/python3.13/site-packages/django/db/backends/utils.py", line 105, in _execute
    return self.cursor.execute(sql, params)
           ~~~~~~~~~~~~~~~~~~~^^^^^^^^^^^^^
  File "/usr/local/lib/python3.13/site-packages/django/db/backends/sqlite3/base.py", line 354, in execute
    return super().execute(query, params)
           ~~~~~~~~~~~~~~~^^^^^^^^^^^^^^^
sqlite3.OperationalError: no such table: products_category

The above exception was the direct cause of the following exception:

Traceback (most recent call last):
  File "/usr/local/lib/python3.13/site-packages/django/core/handlers/exception.py", line 55, in inner
    response = get_response(request)
  File "/usr/local/lib/python3.13/site-packages/django/core/handlers/base.py", line 197, in _get_response
    response = wrapped_callback(request, *callback_args, **callback_kwargs)
  File "/usr/local/lib/python3.13/site-packages/django/contrib/admin/options.py", line 718, in wrapper
    return self.admin_site.admin_view(view)(*args, **kwargs)
           ~~~~~~~~~~~~~~~~~~~~~~~~~~~~~~~~^^^^^^^^^^^^^^^^^
  File "/usr/local/lib/python3.13/site-packages/django/utils/decorators.py", line 188, in _view_wrapper
    result = _process_exception(request, e)
  File "/usr/local/lib/python3.13/site-packages/django/utils/decorators.py", line 186, in _view_wrapper
    response = view_func(request, *args, **kwargs)
  File "/usr/local/lib/python3.13/site-packages/django/views/decorators/cache.py", line 80, in _view_wrapper
    response = view_func(request, *args, **kwargs)
  File "/usr/local/lib/python3.13/site-packages/django/contrib/admin/sites.py", line 241, in inner
    return view(request, *args, **kwargs)
  File "/usr/local/lib/python3.13/site-packages/django/contrib/admin/options.py", line 1961, in add_view
    return self.changeform_view(request, None, form_url, extra_context)
           ~~~~~~~~~~~~~~~~~~~~^^^^^^^^^^^^^^^^^^^^^^^^^^^^^^^^^^^^^^^^
  File "/usr/local/lib/python3.13/site-packages/django/utils/decorators.py", line 48, in _wrapper
    return bound_method(*args, **kwargs)
  File "/usr/local/lib/python3.13/site-packages/django/utils/decorators.py", line 188, in _view_wrapper
    result = _process_exception(request, e)
  File "/usr/local/lib/python3.13/site-packages/django/utils/decorators.py", line 186, in _view_wrapper
    response = view_func(request, *args, **kwargs)
  File "/usr/local/lib/python3.13/site-packages/django/contrib/admin/options.py", line 1820, in changeform_view
    return self._changeform_view(request, object_id, form_url, extra_context)
           ~~~~~~~~~~~~~~~~~~~~~^^^^^^^^^^^^^^^^^^^^^^^^^^^^^^^^^^^^^^^^^^^^^
  File "/usr/local/lib/python3.13/site-packages/django/contrib/admin/options.py", line 1871, in _changeform_view
    self.save_model(request, new_object, form, not add)
    ~~~~~~~~~~~~~~~^^^^^^^^^^^^^^^^^^^^^^^^^^^^^^^^^^^^
  File "/usr/local/lib/python3.13/site-packages/django/contrib/admin/options.py", line 1294, in save_model
    obj.save()
    ~~~~~~~~^^
  File "/usr/local/lib/python3.13/site-packages/django/db/models/base.py", line 891, in save
    self.save_base(
    ~~~~~~~~~~~~~~^
        using=using,
        ^^^^^^^^^^^^
    ...<2 lines>...
        update_fields=update_fields,
        ^^^^^^^^^^^^^^^^^^^^^^^^^^^^
    )
    ^
  File "/usr/local/lib/python3.13/site-packages/django/db/models/base.py", line 997, in save_base
    updated = self._save_table(
        raw,
    ...<4 lines>...
        update_fields,
    )
  File "/usr/local/lib/python3.13/site-packages/django/db/models/base.py", line 1160, in _save_table
    results = self._do_insert(
        cls._base_manager, using, fields, returning_fields, raw
    )
  File "/usr/local/lib/python3.13/site-packages/django/db/models/base.py", line 1201, in _do_insert
    return manager._insert(
           ~~~~~~~~~~~~~~~^
        [self],
        ^^^^^^^
    ...<3 lines>...
        raw=raw,
        ^^^^^^^^
    )
    ^
  File "/usr/local/lib/python3.13/site-packages/django/db/models/manager.py", line 87, in manager_method
    return getattr(self.get_queryset(), name)(*args, **kwargs)
           ~~~~~~~~~~~~~~~~~~~~~~~~~~~~~~~~~~^^^^^^^^^^^^^^^^^
  File "/usr/local/lib/python3.13/site-packages/django/db/models/query.py", line 1847, in _insert
    return query.get_compiler(using=using).execute_sql(returning_fields)
           ~~~~~~~~~~~~~~~~~~~~~~~~~~~~~~~~~~~~~~~~~~~^^^^^^^^^^^^^^^^^^
  File "/usr/local/lib/python3.13/site-packages/django/db/models/sql/compiler.py", line 1836, in execute_sql
    cursor.execute(sql, params)
    ~~~~~~~~~~~~~~^^^^^^^^^^^^^
  File "/usr/local/lib/python3.13/site-packages/django/db/backends/utils.py", line 122, in execute
    return super().execute(sql, params)
           ~~~~~~~~~~~~~~~^^^^^^^^^^^^^
  File "/usr/local/lib/python3.13/site-packages/django/db/backends/utils.py", line 79, in execute
    return self._execute_with_wrappers(
           ~~~~~~~~~~~~~~~~~~~~~~~~~~~^
        sql, params, many=False, executor=self._execute
        ^^^^^^^^^^^^^^^^^^^^^^^^^^^^^^^^^^^^^^^^^^^^^^^
    )
    ^
  File "/usr/local/lib/python3.13/site-packages/django/db/backends/utils.py", line 92, in _execute_with_wrappers
    return executor(sql, params, many, context)
  File "/usr/local/lib/python3.13/site-packages/django/db/backends/utils.py", line 100, in _execute
    with self.db.wrap_database_errors:
         ^^^^^^^^^^^^^^^^^^^^^^^^^^^^
  File "/usr/local/lib/python3.13/site-packages/django/db/utils.py", line 91, in __exit__
    raise dj_exc_value.with_traceback(traceback) from exc_value
  File "/usr/local/lib/python3.13/site-packages/django/db/backends/utils.py", line 105, in _execute
    return self.cursor.execute(sql, params)
           ~~~~~~~~~~~~~~~~~~~^^^^^^^^^^^^^
  File "/usr/local/lib/python3.13/site-packages/django/db/backends/sqlite3/base.py", line 354, in execute
    return super().execute(query, params)
           ~~~~~~~~~~~~~~~^^^^^^^^^^^^^^^
django.db.utils.OperationalError: no such table: products_category
ERROR 2024-12-14 06:50:59,317 basehttp "POST /admin/products/category/add/ HTTP/1.1" 500 197368
ERROR 2024-12-14 07:07:13,736 log Internal Server Error: /api/products/
Traceback (most recent call last):
  File "/usr/local/lib/python3.13/site-packages/django/core/handlers/exception.py", line 55, in inner
    response = get_response(request)
  File "/usr/local/lib/python3.13/site-packages/django/core/handlers/base.py", line 197, in _get_response
    response = wrapped_callback(request, *callback_args, **callback_kwargs)
  File "/usr/local/lib/python3.13/site-packages/django/views/decorators/csrf.py", line 65, in _view_wrapper
    return view_func(request, *args, **kwargs)
  File "/usr/local/lib/python3.13/site-packages/django/views/generic/base.py", line 104, in view
    return self.dispatch(request, *args, **kwargs)
           ~~~~~~~~~~~~~^^^^^^^^^^^^^^^^^^^^^^^^^^
  File "/usr/local/lib/python3.13/site-packages/rest_framework/views.py", line 509, in dispatch
    response = self.handle_exception(exc)
  File "/usr/local/lib/python3.13/site-packages/rest_framework/views.py", line 469, in handle_exception
    self.raise_uncaught_exception(exc)
    ~~~~~~~~~~~~~~~~~~~~~~~~~~~~~^^^^^
  File "/usr/local/lib/python3.13/site-packages/rest_framework/views.py", line 480, in raise_uncaught_exception
    raise exc
  File "/usr/local/lib/python3.13/site-packages/rest_framework/views.py", line 506, in dispatch
    response = handler(request, *args, **kwargs)
TypeError: ProductAPIView.delete() missing 1 required positional argument: 'product_id'
ERROR 2024-12-14 07:07:13,741 basehttp "DELETE /api/products/ HTTP/1.1" 500 82306
ERROR 2025-01-25 18:01:21,497 log Internal Server Error: /admin/login/
Traceback (most recent call last):
  File "/usr/local/lib/python3.13/site-packages/django/db/backends/utils.py", line 105, in _execute
    return self.cursor.execute(sql, params)
           ~~~~~~~~~~~~~~~~~~~^^^^^^^^^^^^^
  File "/usr/local/lib/python3.13/site-packages/django/db/backends/sqlite3/base.py", line 354, in execute
    return super().execute(query, params)
           ~~~~~~~~~~~~~~~^^^^^^^^^^^^^^^
sqlite3.OperationalError: no such column: common_customuser.role_id

The above exception was the direct cause of the following exception:

Traceback (most recent call last):
  File "/usr/local/lib/python3.13/site-packages/django/core/handlers/exception.py", line 55, in inner
    response = get_response(request)
  File "/usr/local/lib/python3.13/site-packages/django/core/handlers/base.py", line 197, in _get_response
    response = wrapped_callback(request, *callback_args, **callback_kwargs)
  File "/usr/local/lib/python3.13/site-packages/django/utils/decorators.py", line 48, in _wrapper
    return bound_method(*args, **kwargs)
  File "/usr/local/lib/python3.13/site-packages/django/views/decorators/cache.py", line 80, in _view_wrapper
    response = view_func(request, *args, **kwargs)
  File "/usr/local/lib/python3.13/site-packages/django/contrib/admin/sites.py", line 444, in login
    return LoginView.as_view(**defaults)(request)
           ~~~~~~~~~~~~~~~~~~~~~~~~~~~~~^^^^^^^^^
  File "/usr/local/lib/python3.13/site-packages/django/views/generic/base.py", line 104, in view
    return self.dispatch(request, *args, **kwargs)
           ~~~~~~~~~~~~~^^^^^^^^^^^^^^^^^^^^^^^^^^
  File "/usr/local/lib/python3.13/site-packages/django/utils/decorators.py", line 48, in _wrapper
    return bound_method(*args, **kwargs)
  File "/usr/local/lib/python3.13/site-packages/django/utils/decorators.py", line 48, in _wrapper
    return bound_method(*args, **kwargs)
  File "/usr/local/lib/python3.13/site-packages/django/views/decorators/debug.py", line 143, in sensitive_post_parameters_wrapper
    return view(request, *args, **kwargs)
  File "/usr/local/lib/python3.13/site-packages/django/utils/decorators.py", line 48, in _wrapper
    return bound_method(*args, **kwargs)
  File "/usr/local/lib/python3.13/site-packages/django/utils/decorators.py", line 188, in _view_wrapper
    result = _process_exception(request, e)
  File "/usr/local/lib/python3.13/site-packages/django/utils/decorators.py", line 186, in _view_wrapper
    response = view_func(request, *args, **kwargs)
  File "/usr/local/lib/python3.13/site-packages/django/utils/decorators.py", line 48, in _wrapper
    return bound_method(*args, **kwargs)
  File "/usr/local/lib/python3.13/site-packages/django/views/decorators/cache.py", line 80, in _view_wrapper
    response = view_func(request, *args, **kwargs)
  File "/usr/local/lib/python3.13/site-packages/django/contrib/auth/views.py", line 89, in dispatch
    return super().dispatch(request, *args, **kwargs)
           ~~~~~~~~~~~~~~~~^^^^^^^^^^^^^^^^^^^^^^^^^^
  File "/usr/local/lib/python3.13/site-packages/django/views/generic/base.py", line 143, in dispatch
    return handler(request, *args, **kwargs)
  File "/usr/local/lib/python3.13/site-packages/django/views/generic/edit.py", line 150, in post
    if form.is_valid():
       ~~~~~~~~~~~~~^^
  File "/usr/local/lib/python3.13/site-packages/django/forms/forms.py", line 197, in is_valid
    return self.is_bound and not self.errors
                                 ^^^^^^^^^^^
  File "/usr/local/lib/python3.13/site-packages/django/forms/forms.py", line 192, in errors
    self.full_clean()
    ~~~~~~~~~~~~~~~^^
  File "/usr/local/lib/python3.13/site-packages/django/forms/forms.py", line 326, in full_clean
    self._clean_form()
    ~~~~~~~~~~~~~~~~^^
  File "/usr/local/lib/python3.13/site-packages/django/forms/forms.py", line 342, in _clean_form
    cleaned_data = self.clean()
  File "/usr/local/lib/python3.13/site-packages/django/contrib/auth/forms.py", line 356, in clean
    self.user_cache = authenticate(
                      ~~~~~~~~~~~~^
        self.request, username=username, password=password
        ^^^^^^^^^^^^^^^^^^^^^^^^^^^^^^^^^^^^^^^^^^^^^^^^^^
    )
    ^
  File "/usr/local/lib/python3.13/site-packages/django/views/decorators/debug.py", line 75, in sensitive_variables_wrapper
    return func(*func_args, **func_kwargs)
  File "/usr/local/lib/python3.13/site-packages/django/contrib/auth/__init__.py", line 79, in authenticate
    user = backend.authenticate(request, **credentials)
  File "/app/common/backends.py", line 15, in authenticate
    user=UserModel.objects.get(email=email)
  File "/usr/local/lib/python3.13/site-packages/django/db/models/manager.py", line 87, in manager_method
    return getattr(self.get_queryset(), name)(*args, **kwargs)
           ~~~~~~~~~~~~~~~~~~~~~~~~~~~~~~~~~~^^^^^^^^^^^^^^^^^
  File "/usr/local/lib/python3.13/site-packages/django/db/models/query.py", line 645, in get
    num = len(clone)
  File "/usr/local/lib/python3.13/site-packages/django/db/models/query.py", line 382, in __len__
    self._fetch_all()
    ~~~~~~~~~~~~~~~^^
  File "/usr/local/lib/python3.13/site-packages/django/db/models/query.py", line 1928, in _fetch_all
    self._result_cache = list(self._iterable_class(self))
                         ~~~~^^^^^^^^^^^^^^^^^^^^^^^^^^^^
  File "/usr/local/lib/python3.13/site-packages/django/db/models/query.py", line 91, in __iter__
    results = compiler.execute_sql(
        chunked_fetch=self.chunked_fetch, chunk_size=self.chunk_size
    )
  File "/usr/local/lib/python3.13/site-packages/django/db/models/sql/compiler.py", line 1574, in execute_sql
    cursor.execute(sql, params)
    ~~~~~~~~~~~~~~^^^^^^^^^^^^^
  File "/usr/local/lib/python3.13/site-packages/django/db/backends/utils.py", line 122, in execute
    return super().execute(sql, params)
           ~~~~~~~~~~~~~~~^^^^^^^^^^^^^
  File "/usr/local/lib/python3.13/site-packages/django/db/backends/utils.py", line 79, in execute
    return self._execute_with_wrappers(
           ~~~~~~~~~~~~~~~~~~~~~~~~~~~^
        sql, params, many=False, executor=self._execute
        ^^^^^^^^^^^^^^^^^^^^^^^^^^^^^^^^^^^^^^^^^^^^^^^
    )
    ^
  File "/usr/local/lib/python3.13/site-packages/django/db/backends/utils.py", line 92, in _execute_with_wrappers
    return executor(sql, params, many, context)
  File "/usr/local/lib/python3.13/site-packages/django/db/backends/utils.py", line 100, in _execute
    with self.db.wrap_database_errors:
         ^^^^^^^^^^^^^^^^^^^^^^^^^^^^
  File "/usr/local/lib/python3.13/site-packages/django/db/utils.py", line 91, in __exit__
    raise dj_exc_value.with_traceback(traceback) from exc_value
  File "/usr/local/lib/python3.13/site-packages/django/db/backends/utils.py", line 105, in _execute
    return self.cursor.execute(sql, params)
           ~~~~~~~~~~~~~~~~~~~^^^^^^^^^^^^^
  File "/usr/local/lib/python3.13/site-packages/django/db/backends/sqlite3/base.py", line 354, in execute
    return super().execute(query, params)
           ~~~~~~~~~~~~~~~^^^^^^^^^^^^^^^
django.db.utils.OperationalError: no such column: common_customuser.role_id
ERROR 2025-01-25 18:01:21,503 basehttp "POST /admin/login/?next=/admin/ HTTP/1.1" 500 237442
ERROR 2025-01-25 18:03:03,203 log Internal Server Error: /common/signup/
Traceback (most recent call last):
  File "/usr/local/lib/python3.13/site-packages/django/db/backends/utils.py", line 105, in _execute
    return self.cursor.execute(sql, params)
           ~~~~~~~~~~~~~~~~~~~^^^^^^^^^^^^^
  File "/usr/local/lib/python3.13/site-packages/django/db/backends/sqlite3/base.py", line 354, in execute
    return super().execute(query, params)
           ~~~~~~~~~~~~~~~^^^^^^^^^^^^^^^
sqlite3.OperationalError: no such table: common_role

The above exception was the direct cause of the following exception:

Traceback (most recent call last):
  File "/usr/local/lib/python3.13/site-packages/django/core/handlers/exception.py", line 55, in inner
    response = get_response(request)
  File "/usr/local/lib/python3.13/site-packages/django/core/handlers/base.py", line 197, in _get_response
    response = wrapped_callback(request, *callback_args, **callback_kwargs)
  File "/usr/local/lib/python3.13/site-packages/django/views/decorators/csrf.py", line 65, in _view_wrapper
    return view_func(request, *args, **kwargs)
  File "/usr/local/lib/python3.13/site-packages/django/views/generic/base.py", line 104, in view
    return self.dispatch(request, *args, **kwargs)
           ~~~~~~~~~~~~~^^^^^^^^^^^^^^^^^^^^^^^^^^
  File "/usr/local/lib/python3.13/site-packages/rest_framework/views.py", line 509, in dispatch
    response = self.handle_exception(exc)
  File "/usr/local/lib/python3.13/site-packages/rest_framework/views.py", line 469, in handle_exception
    self.raise_uncaught_exception(exc)
    ~~~~~~~~~~~~~~~~~~~~~~~~~~~~~^^^^^
  File "/usr/local/lib/python3.13/site-packages/rest_framework/views.py", line 480, in raise_uncaught_exception
    raise exc
  File "/usr/local/lib/python3.13/site-packages/rest_framework/views.py", line 506, in dispatch
    response = handler(request, *args, **kwargs)
  File "/app/common/views.py", line 21, in post
    user = CustomUserHandler.signup_user(request.data)
  File "/app/common/handlers.py", line 29, in signup_user
    user = serializer.save()
  File "/usr/local/lib/python3.13/site-packages/rest_framework/serializers.py", line 208, in save
    self.instance = self.create(validated_data)
                    ~~~~~~~~~~~^^^^^^^^^^^^^^^^
  File "/app/common/serializers.py", line 30, in create
    role = Role.objects.get(name=role_name)
  File "/usr/local/lib/python3.13/site-packages/django/db/models/manager.py", line 87, in manager_method
    return getattr(self.get_queryset(), name)(*args, **kwargs)
           ~~~~~~~~~~~~~~~~~~~~~~~~~~~~~~~~~~^^^^^^^^^^^^^^^^^
  File "/usr/local/lib/python3.13/site-packages/django/db/models/query.py", line 645, in get
    num = len(clone)
  File "/usr/local/lib/python3.13/site-packages/django/db/models/query.py", line 382, in __len__
    self._fetch_all()
    ~~~~~~~~~~~~~~~^^
  File "/usr/local/lib/python3.13/site-packages/django/db/models/query.py", line 1928, in _fetch_all
    self._result_cache = list(self._iterable_class(self))
                         ~~~~^^^^^^^^^^^^^^^^^^^^^^^^^^^^
  File "/usr/local/lib/python3.13/site-packages/django/db/models/query.py", line 91, in __iter__
    results = compiler.execute_sql(
        chunked_fetch=self.chunked_fetch, chunk_size=self.chunk_size
    )
  File "/usr/local/lib/python3.13/site-packages/django/db/models/sql/compiler.py", line 1574, in execute_sql
    cursor.execute(sql, params)
    ~~~~~~~~~~~~~~^^^^^^^^^^^^^
  File "/usr/local/lib/python3.13/site-packages/django/db/backends/utils.py", line 122, in execute
    return super().execute(sql, params)
           ~~~~~~~~~~~~~~~^^^^^^^^^^^^^
  File "/usr/local/lib/python3.13/site-packages/django/db/backends/utils.py", line 79, in execute
    return self._execute_with_wrappers(
           ~~~~~~~~~~~~~~~~~~~~~~~~~~~^
        sql, params, many=False, executor=self._execute
        ^^^^^^^^^^^^^^^^^^^^^^^^^^^^^^^^^^^^^^^^^^^^^^^
    )
    ^
  File "/usr/local/lib/python3.13/site-packages/django/db/backends/utils.py", line 92, in _execute_with_wrappers
    return executor(sql, params, many, context)
  File "/usr/local/lib/python3.13/site-packages/django/db/backends/utils.py", line 100, in _execute
    with self.db.wrap_database_errors:
         ^^^^^^^^^^^^^^^^^^^^^^^^^^^^
  File "/usr/local/lib/python3.13/site-packages/django/db/utils.py", line 91, in __exit__
    raise dj_exc_value.with_traceback(traceback) from exc_value
  File "/usr/local/lib/python3.13/site-packages/django/db/backends/utils.py", line 105, in _execute
    return self.cursor.execute(sql, params)
           ~~~~~~~~~~~~~~~~~~~^^^^^^^^^^^^^
  File "/usr/local/lib/python3.13/site-packages/django/db/backends/sqlite3/base.py", line 354, in execute
    return super().execute(query, params)
           ~~~~~~~~~~~~~~~^^^^^^^^^^^^^^^
django.db.utils.OperationalError: no such table: common_role
ERROR 2025-01-25 18:03:03,206 basehttp "POST /common/signup/ HTTP/1.1" 500 168401
ERROR 2025-01-25 18:11:30,956 log Internal Server Error: /common/login/
Traceback (most recent call last):
  File "/usr/local/lib/python3.13/site-packages/django/db/backends/utils.py", line 105, in _execute
    return self.cursor.execute(sql, params)
           ~~~~~~~~~~~~~~~~~~~^^^^^^^^^^^^^
  File "/usr/local/lib/python3.13/site-packages/django/db/backends/sqlite3/base.py", line 354, in execute
    return super().execute(query, params)
           ~~~~~~~~~~~~~~~^^^^^^^^^^^^^^^
sqlite3.OperationalError: no such column: common_customuser.role_id

The above exception was the direct cause of the following exception:

Traceback (most recent call last):
  File "/usr/local/lib/python3.13/site-packages/django/core/handlers/exception.py", line 55, in inner
    response = get_response(request)
  File "/usr/local/lib/python3.13/site-packages/django/core/handlers/base.py", line 197, in _get_response
    response = wrapped_callback(request, *callback_args, **callback_kwargs)
  File "/usr/local/lib/python3.13/site-packages/django/views/decorators/csrf.py", line 65, in _view_wrapper
    return view_func(request, *args, **kwargs)
  File "/usr/local/lib/python3.13/site-packages/django/views/generic/base.py", line 104, in view
    return self.dispatch(request, *args, **kwargs)
           ~~~~~~~~~~~~~^^^^^^^^^^^^^^^^^^^^^^^^^^
  File "/usr/local/lib/python3.13/site-packages/rest_framework/views.py", line 509, in dispatch
    response = self.handle_exception(exc)
  File "/usr/local/lib/python3.13/site-packages/rest_framework/views.py", line 469, in handle_exception
    self.raise_uncaught_exception(exc)
    ~~~~~~~~~~~~~~~~~~~~~~~~~~~~~^^^^^
  File "/usr/local/lib/python3.13/site-packages/rest_framework/views.py", line 480, in raise_uncaught_exception
    raise exc
  File "/usr/local/lib/python3.13/site-packages/rest_framework/views.py", line 506, in dispatch
    response = handler(request, *args, **kwargs)
  File "/app/common/views.py", line 33, in post
    user = authenticate(request, email=email, password=password)
  File "/usr/local/lib/python3.13/site-packages/django/views/decorators/debug.py", line 75, in sensitive_variables_wrapper
    return func(*func_args, **func_kwargs)
  File "/usr/local/lib/python3.13/site-packages/django/contrib/auth/__init__.py", line 79, in authenticate
    user = backend.authenticate(request, **credentials)
  File "/app/common/backends.py", line 15, in authenticate
    user=UserModel.objects.get(email=email)
  File "/usr/local/lib/python3.13/site-packages/django/db/models/manager.py", line 87, in manager_method
    return getattr(self.get_queryset(), name)(*args, **kwargs)
           ~~~~~~~~~~~~~~~~~~~~~~~~~~~~~~~~~~^^^^^^^^^^^^^^^^^
  File "/usr/local/lib/python3.13/site-packages/django/db/models/query.py", line 645, in get
    num = len(clone)
  File "/usr/local/lib/python3.13/site-packages/django/db/models/query.py", line 382, in __len__
    self._fetch_all()
    ~~~~~~~~~~~~~~~^^
  File "/usr/local/lib/python3.13/site-packages/django/db/models/query.py", line 1928, in _fetch_all
    self._result_cache = list(self._iterable_class(self))
                         ~~~~^^^^^^^^^^^^^^^^^^^^^^^^^^^^
  File "/usr/local/lib/python3.13/site-packages/django/db/models/query.py", line 91, in __iter__
    results = compiler.execute_sql(
        chunked_fetch=self.chunked_fetch, chunk_size=self.chunk_size
    )
  File "/usr/local/lib/python3.13/site-packages/django/db/models/sql/compiler.py", line 1574, in execute_sql
    cursor.execute(sql, params)
    ~~~~~~~~~~~~~~^^^^^^^^^^^^^
  File "/usr/local/lib/python3.13/site-packages/django/db/backends/utils.py", line 122, in execute
    return super().execute(sql, params)
           ~~~~~~~~~~~~~~~^^^^^^^^^^^^^
  File "/usr/local/lib/python3.13/site-packages/django/db/backends/utils.py", line 79, in execute
    return self._execute_with_wrappers(
           ~~~~~~~~~~~~~~~~~~~~~~~~~~~^
        sql, params, many=False, executor=self._execute
        ^^^^^^^^^^^^^^^^^^^^^^^^^^^^^^^^^^^^^^^^^^^^^^^
    )
    ^
  File "/usr/local/lib/python3.13/site-packages/django/db/backends/utils.py", line 92, in _execute_with_wrappers
    return executor(sql, params, many, context)
  File "/usr/local/lib/python3.13/site-packages/django/db/backends/utils.py", line 100, in _execute
    with self.db.wrap_database_errors:
         ^^^^^^^^^^^^^^^^^^^^^^^^^^^^
  File "/usr/local/lib/python3.13/site-packages/django/db/utils.py", line 91, in __exit__
    raise dj_exc_value.with_traceback(traceback) from exc_value
  File "/usr/local/lib/python3.13/site-packages/django/db/backends/utils.py", line 105, in _execute
    return self.cursor.execute(sql, params)
           ~~~~~~~~~~~~~~~~~~~^^^^^^^^^^^^^
  File "/usr/local/lib/python3.13/site-packages/django/db/backends/sqlite3/base.py", line 354, in execute
    return super().execute(query, params)
           ~~~~~~~~~~~~~~~^^^^^^^^^^^^^^^
django.db.utils.OperationalError: no such column: common_customuser.role_id
ERROR 2025-01-25 18:11:30,960 basehttp "POST /common/login/ HTTP/1.1" 500 173794
ERROR 2025-01-25 18:12:37,509 log Internal Server Error: /common/login/
Traceback (most recent call last):
  File "/usr/local/lib/python3.13/site-packages/django/db/backends/utils.py", line 105, in _execute
    return self.cursor.execute(sql, params)
           ~~~~~~~~~~~~~~~~~~~^^^^^^^^^^^^^
  File "/usr/local/lib/python3.13/site-packages/django/db/backends/sqlite3/base.py", line 354, in execute
    return super().execute(query, params)
           ~~~~~~~~~~~~~~~^^^^^^^^^^^^^^^
sqlite3.OperationalError: no such column: common_customuser.role_id

The above exception was the direct cause of the following exception:

Traceback (most recent call last):
  File "/usr/local/lib/python3.13/site-packages/django/core/handlers/exception.py", line 55, in inner
    response = get_response(request)
  File "/usr/local/lib/python3.13/site-packages/django/core/handlers/base.py", line 197, in _get_response
    response = wrapped_callback(request, *callback_args, **callback_kwargs)
  File "/usr/local/lib/python3.13/site-packages/django/views/decorators/csrf.py", line 65, in _view_wrapper
    return view_func(request, *args, **kwargs)
  File "/usr/local/lib/python3.13/site-packages/django/views/generic/base.py", line 104, in view
    return self.dispatch(request, *args, **kwargs)
           ~~~~~~~~~~~~~^^^^^^^^^^^^^^^^^^^^^^^^^^
  File "/usr/local/lib/python3.13/site-packages/rest_framework/views.py", line 509, in dispatch
    response = self.handle_exception(exc)
  File "/usr/local/lib/python3.13/site-packages/rest_framework/views.py", line 469, in handle_exception
    self.raise_uncaught_exception(exc)
    ~~~~~~~~~~~~~~~~~~~~~~~~~~~~~^^^^^
  File "/usr/local/lib/python3.13/site-packages/rest_framework/views.py", line 480, in raise_uncaught_exception
    raise exc
  File "/usr/local/lib/python3.13/site-packages/rest_framework/views.py", line 506, in dispatch
    response = handler(request, *args, **kwargs)
  File "/app/common/views.py", line 33, in post
    user = authenticate(request, email=email, password=password)
  File "/usr/local/lib/python3.13/site-packages/django/views/decorators/debug.py", line 75, in sensitive_variables_wrapper
    return func(*func_args, **func_kwargs)
  File "/usr/local/lib/python3.13/site-packages/django/contrib/auth/__init__.py", line 79, in authenticate
    user = backend.authenticate(request, **credentials)
  File "/app/common/backends.py", line 15, in authenticate
    user=UserModel.objects.get(email=email)
  File "/usr/local/lib/python3.13/site-packages/django/db/models/manager.py", line 87, in manager_method
    return getattr(self.get_queryset(), name)(*args, **kwargs)
           ~~~~~~~~~~~~~~~~~~~~~~~~~~~~~~~~~~^^^^^^^^^^^^^^^^^
  File "/usr/local/lib/python3.13/site-packages/django/db/models/query.py", line 645, in get
    num = len(clone)
  File "/usr/local/lib/python3.13/site-packages/django/db/models/query.py", line 382, in __len__
    self._fetch_all()
    ~~~~~~~~~~~~~~~^^
  File "/usr/local/lib/python3.13/site-packages/django/db/models/query.py", line 1928, in _fetch_all
    self._result_cache = list(self._iterable_class(self))
                         ~~~~^^^^^^^^^^^^^^^^^^^^^^^^^^^^
  File "/usr/local/lib/python3.13/site-packages/django/db/models/query.py", line 91, in __iter__
    results = compiler.execute_sql(
        chunked_fetch=self.chunked_fetch, chunk_size=self.chunk_size
    )
  File "/usr/local/lib/python3.13/site-packages/django/db/models/sql/compiler.py", line 1574, in execute_sql
    cursor.execute(sql, params)
    ~~~~~~~~~~~~~~^^^^^^^^^^^^^
  File "/usr/local/lib/python3.13/site-packages/django/db/backends/utils.py", line 122, in execute
    return super().execute(sql, params)
           ~~~~~~~~~~~~~~~^^^^^^^^^^^^^
  File "/usr/local/lib/python3.13/site-packages/django/db/backends/utils.py", line 79, in execute
    return self._execute_with_wrappers(
           ~~~~~~~~~~~~~~~~~~~~~~~~~~~^
        sql, params, many=False, executor=self._execute
        ^^^^^^^^^^^^^^^^^^^^^^^^^^^^^^^^^^^^^^^^^^^^^^^
    )
    ^
  File "/usr/local/lib/python3.13/site-packages/django/db/backends/utils.py", line 92, in _execute_with_wrappers
    return executor(sql, params, many, context)
  File "/usr/local/lib/python3.13/site-packages/django/db/backends/utils.py", line 100, in _execute
    with self.db.wrap_database_errors:
         ^^^^^^^^^^^^^^^^^^^^^^^^^^^^
  File "/usr/local/lib/python3.13/site-packages/django/db/utils.py", line 91, in __exit__
    raise dj_exc_value.with_traceback(traceback) from exc_value
  File "/usr/local/lib/python3.13/site-packages/django/db/backends/utils.py", line 105, in _execute
    return self.cursor.execute(sql, params)
           ~~~~~~~~~~~~~~~~~~~^^^^^^^^^^^^^
  File "/usr/local/lib/python3.13/site-packages/django/db/backends/sqlite3/base.py", line 354, in execute
    return super().execute(query, params)
           ~~~~~~~~~~~~~~~^^^^^^^^^^^^^^^
django.db.utils.OperationalError: no such column: common_customuser.role_id
ERROR 2025-01-25 18:12:37,511 basehttp "POST /common/login/ HTTP/1.1" 500 173668
