ERROR 2024-12-08 14:28:14,171 log Internal Server Error: /common/currentuser/
Traceback (most recent call last):
  File "/usr/local/lib/python3.13/site-packages/django/db/backends/utils.py", line 105, in _execute
    return self.cursor.execute(sql, params)
           ~~~~~~~~~~~~~~~~~~~^^^^^^^^^^^^^
  File "/usr/local/lib/python3.13/site-packages/django/db/backends/sqlite3/base.py", line 354, in execute
    return super().execute(query, params)
           ~~~~~~~~~~~~~~~^^^^^^^^^^^^^^^
sqlite3.OperationalError: no such table: common_userprofile

The above exception was the direct cause of the following exception:

Traceback (most recent call last):
  File "/usr/local/lib/python3.13/site-packages/django/core/handlers/exception.py", line 55, in inner
    response = get_response(request)
  File "/usr/local/lib/python3.13/site-packages/django/core/handlers/base.py", line 197, in _get_response
    response = wrapped_callback(request, *callback_args, **callback_kwargs)
  File "/usr/local/lib/python3.13/site-packages/django/views/decorators/csrf.py", line 65, in _view_wrapper
    return view_func(request, *args, **kwargs)
  File "/usr/local/lib/python3.13/site-packages/django/views/generic/base.py", line 104, in view
    return self.dispatch(request, *args, **kwargs)
           ~~~~~~~~~~~~~^^^^^^^^^^^^^^^^^^^^^^^^^^
  File "/usr/local/lib/python3.13/site-packages/rest_framework/views.py", line 509, in dispatch
    response = self.handle_exception(exc)
  File "/usr/local/lib/python3.13/site-packages/rest_framework/views.py", line 469, in handle_exception
    self.raise_uncaught_exception(exc)
    ~~~~~~~~~~~~~~~~~~~~~~~~~~~~~^^^^^
  File "/usr/local/lib/python3.13/site-packages/rest_framework/views.py", line 480, in raise_uncaught_exception
    raise exc
  File "/usr/local/lib/python3.13/site-packages/rest_framework/views.py", line 506, in dispatch
    response = handler(request, *args, **kwargs)
  File "/app/common/views.py", line 89, in get
    userprofile = UserProfile.objects.get(user=user)
  File "/usr/local/lib/python3.13/site-packages/django/db/models/manager.py", line 87, in manager_method
    return getattr(self.get_queryset(), name)(*args, **kwargs)
           ~~~~~~~~~~~~~~~~~~~~~~~~~~~~~~~~~~^^^^^^^^^^^^^^^^^
  File "/usr/local/lib/python3.13/site-packages/django/db/models/query.py", line 645, in get
    num = len(clone)
  File "/usr/local/lib/python3.13/site-packages/django/db/models/query.py", line 382, in __len__
    self._fetch_all()
    ~~~~~~~~~~~~~~~^^
  File "/usr/local/lib/python3.13/site-packages/django/db/models/query.py", line 1928, in _fetch_all
    self._result_cache = list(self._iterable_class(self))
                         ~~~~^^^^^^^^^^^^^^^^^^^^^^^^^^^^
  File "/usr/local/lib/python3.13/site-packages/django/db/models/query.py", line 91, in __iter__
    results = compiler.execute_sql(
        chunked_fetch=self.chunked_fetch, chunk_size=self.chunk_size
    )
  File "/usr/local/lib/python3.13/site-packages/django/db/models/sql/compiler.py", line 1574, in execute_sql
    cursor.execute(sql, params)
    ~~~~~~~~~~~~~~^^^^^^^^^^^^^
  File "/usr/local/lib/python3.13/site-packages/django/db/backends/utils.py", line 122, in execute
    return super().execute(sql, params)
           ~~~~~~~~~~~~~~~^^^^^^^^^^^^^
  File "/usr/local/lib/python3.13/site-packages/django/db/backends/utils.py", line 79, in execute
    return self._execute_with_wrappers(
           ~~~~~~~~~~~~~~~~~~~~~~~~~~~^
        sql, params, many=False, executor=self._execute
        ^^^^^^^^^^^^^^^^^^^^^^^^^^^^^^^^^^^^^^^^^^^^^^^
    )
    ^
  File "/usr/local/lib/python3.13/site-packages/django/db/backends/utils.py", line 92, in _execute_with_wrappers
    return executor(sql, params, many, context)
  File "/usr/local/lib/python3.13/site-packages/django/db/backends/utils.py", line 100, in _execute
    with self.db.wrap_database_errors:
         ^^^^^^^^^^^^^^^^^^^^^^^^^^^^
  File "/usr/local/lib/python3.13/site-packages/django/db/utils.py", line 91, in __exit__
    raise dj_exc_value.with_traceback(traceback) from exc_value
  File "/usr/local/lib/python3.13/site-packages/django/db/backends/utils.py", line 105, in _execute
    return self.cursor.execute(sql, params)
           ~~~~~~~~~~~~~~~~~~~^^^^^^^^^^^^^
  File "/usr/local/lib/python3.13/site-packages/django/db/backends/sqlite3/base.py", line 354, in execute
    return super().execute(query, params)
           ~~~~~~~~~~~~~~~^^^^^^^^^^^^^^^
django.db.utils.OperationalError: no such table: common_userprofile
ERROR 2024-12-08 14:28:14,183 basehttp "GET /common/currentuser/ HTTP/1.1" 500 158902
ERROR 2024-12-08 14:36:31,726 log Internal Server Error: /common/currentuser/
Traceback (most recent call last):
  File "/usr/local/lib/python3.13/site-packages/django/db/backends/utils.py", line 105, in _execute
    return self.cursor.execute(sql, params)
           ~~~~~~~~~~~~~~~~~~~^^^^^^^^^^^^^
  File "/usr/local/lib/python3.13/site-packages/django/db/backends/sqlite3/base.py", line 354, in execute
    return super().execute(query, params)
           ~~~~~~~~~~~~~~~^^^^^^^^^^^^^^^
sqlite3.OperationalError: no such table: common_userprofile

The above exception was the direct cause of the following exception:

Traceback (most recent call last):
  File "/usr/local/lib/python3.13/site-packages/django/core/handlers/exception.py", line 55, in inner
    response = get_response(request)
  File "/usr/local/lib/python3.13/site-packages/django/core/handlers/base.py", line 197, in _get_response
    response = wrapped_callback(request, *callback_args, **callback_kwargs)
  File "/usr/local/lib/python3.13/site-packages/django/views/decorators/csrf.py", line 65, in _view_wrapper
    return view_func(request, *args, **kwargs)
  File "/usr/local/lib/python3.13/site-packages/django/views/generic/base.py", line 104, in view
    return self.dispatch(request, *args, **kwargs)
           ~~~~~~~~~~~~~^^^^^^^^^^^^^^^^^^^^^^^^^^
  File "/usr/local/lib/python3.13/site-packages/rest_framework/views.py", line 509, in dispatch
    response = self.handle_exception(exc)
  File "/usr/local/lib/python3.13/site-packages/rest_framework/views.py", line 469, in handle_exception
    self.raise_uncaught_exception(exc)
    ~~~~~~~~~~~~~~~~~~~~~~~~~~~~~^^^^^
  File "/usr/local/lib/python3.13/site-packages/rest_framework/views.py", line 480, in raise_uncaught_exception
    raise exc
  File "/usr/local/lib/python3.13/site-packages/rest_framework/views.py", line 506, in dispatch
    response = handler(request, *args, **kwargs)
  File "/app/common/views.py", line 89, in get
    userprofile = UserProfile.objects.get(user=user)
  File "/usr/local/lib/python3.13/site-packages/django/db/models/manager.py", line 87, in manager_method
    return getattr(self.get_queryset(), name)(*args, **kwargs)
           ~~~~~~~~~~~~~~~~~~~~~~~~~~~~~~~~~~^^^^^^^^^^^^^^^^^
  File "/usr/local/lib/python3.13/site-packages/django/db/models/query.py", line 645, in get
    num = len(clone)
  File "/usr/local/lib/python3.13/site-packages/django/db/models/query.py", line 382, in __len__
    self._fetch_all()
    ~~~~~~~~~~~~~~~^^
  File "/usr/local/lib/python3.13/site-packages/django/db/models/query.py", line 1928, in _fetch_all
    self._result_cache = list(self._iterable_class(self))
                         ~~~~^^^^^^^^^^^^^^^^^^^^^^^^^^^^
  File "/usr/local/lib/python3.13/site-packages/django/db/models/query.py", line 91, in __iter__
    results = compiler.execute_sql(
        chunked_fetch=self.chunked_fetch, chunk_size=self.chunk_size
    )
  File "/usr/local/lib/python3.13/site-packages/django/db/models/sql/compiler.py", line 1574, in execute_sql
    cursor.execute(sql, params)
    ~~~~~~~~~~~~~~^^^^^^^^^^^^^
  File "/usr/local/lib/python3.13/site-packages/django/db/backends/utils.py", line 122, in execute
    return super().execute(sql, params)
           ~~~~~~~~~~~~~~~^^^^^^^^^^^^^
  File "/usr/local/lib/python3.13/site-packages/django/db/backends/utils.py", line 79, in execute
    return self._execute_with_wrappers(
           ~~~~~~~~~~~~~~~~~~~~~~~~~~~^
        sql, params, many=False, executor=self._execute
        ^^^^^^^^^^^^^^^^^^^^^^^^^^^^^^^^^^^^^^^^^^^^^^^
    )
    ^
  File "/usr/local/lib/python3.13/site-packages/django/db/backends/utils.py", line 92, in _execute_with_wrappers
    return executor(sql, params, many, context)
  File "/usr/local/lib/python3.13/site-packages/django/db/backends/utils.py", line 100, in _execute
    with self.db.wrap_database_errors:
         ^^^^^^^^^^^^^^^^^^^^^^^^^^^^
  File "/usr/local/lib/python3.13/site-packages/django/db/utils.py", line 91, in __exit__
    raise dj_exc_value.with_traceback(traceback) from exc_value
  File "/usr/local/lib/python3.13/site-packages/django/db/backends/utils.py", line 105, in _execute
    return self.cursor.execute(sql, params)
           ~~~~~~~~~~~~~~~~~~~^^^^^^^^^^^^^
  File "/usr/local/lib/python3.13/site-packages/django/db/backends/sqlite3/base.py", line 354, in execute
    return super().execute(query, params)
           ~~~~~~~~~~~~~~~^^^^^^^^^^^^^^^
django.db.utils.OperationalError: no such table: common_userprofile
ERROR 2024-12-08 14:36:31,735 basehttp "GET /common/currentuser/ HTTP/1.1" 500 158902
ERROR 2024-12-08 14:37:29,551 log Internal Server Error: /common/currentuser/
Traceback (most recent call last):
  File "/usr/local/lib/python3.13/site-packages/django/db/backends/utils.py", line 105, in _execute
    return self.cursor.execute(sql, params)
           ~~~~~~~~~~~~~~~~~~~^^^^^^^^^^^^^
  File "/usr/local/lib/python3.13/site-packages/django/db/backends/sqlite3/base.py", line 354, in execute
    return super().execute(query, params)
           ~~~~~~~~~~~~~~~^^^^^^^^^^^^^^^
sqlite3.OperationalError: no such table: common_userprofile

The above exception was the direct cause of the following exception:

Traceback (most recent call last):
  File "/usr/local/lib/python3.13/site-packages/django/core/handlers/exception.py", line 55, in inner
    response = get_response(request)
  File "/usr/local/lib/python3.13/site-packages/django/core/handlers/base.py", line 197, in _get_response
    response = wrapped_callback(request, *callback_args, **callback_kwargs)
  File "/usr/local/lib/python3.13/site-packages/django/views/decorators/csrf.py", line 65, in _view_wrapper
    return view_func(request, *args, **kwargs)
  File "/usr/local/lib/python3.13/site-packages/django/views/generic/base.py", line 104, in view
    return self.dispatch(request, *args, **kwargs)
           ~~~~~~~~~~~~~^^^^^^^^^^^^^^^^^^^^^^^^^^
  File "/usr/local/lib/python3.13/site-packages/rest_framework/views.py", line 509, in dispatch
    response = self.handle_exception(exc)
  File "/usr/local/lib/python3.13/site-packages/rest_framework/views.py", line 469, in handle_exception
    self.raise_uncaught_exception(exc)
    ~~~~~~~~~~~~~~~~~~~~~~~~~~~~~^^^^^
  File "/usr/local/lib/python3.13/site-packages/rest_framework/views.py", line 480, in raise_uncaught_exception
    raise exc
  File "/usr/local/lib/python3.13/site-packages/rest_framework/views.py", line 506, in dispatch
    response = handler(request, *args, **kwargs)
  File "/app/common/views.py", line 89, in get
    userprofile = UserProfile.objects.get(user=user)
  File "/usr/local/lib/python3.13/site-packages/django/db/models/manager.py", line 87, in manager_method
    return getattr(self.get_queryset(), name)(*args, **kwargs)
           ~~~~~~~~~~~~~~~~~~~~~~~~~~~~~~~~~~^^^^^^^^^^^^^^^^^
  File "/usr/local/lib/python3.13/site-packages/django/db/models/query.py", line 645, in get
    num = len(clone)
  File "/usr/local/lib/python3.13/site-packages/django/db/models/query.py", line 382, in __len__
    self._fetch_all()
    ~~~~~~~~~~~~~~~^^
  File "/usr/local/lib/python3.13/site-packages/django/db/models/query.py", line 1928, in _fetch_all
    self._result_cache = list(self._iterable_class(self))
                         ~~~~^^^^^^^^^^^^^^^^^^^^^^^^^^^^
  File "/usr/local/lib/python3.13/site-packages/django/db/models/query.py", line 91, in __iter__
    results = compiler.execute_sql(
        chunked_fetch=self.chunked_fetch, chunk_size=self.chunk_size
    )
  File "/usr/local/lib/python3.13/site-packages/django/db/models/sql/compiler.py", line 1574, in execute_sql
    cursor.execute(sql, params)
    ~~~~~~~~~~~~~~^^^^^^^^^^^^^
  File "/usr/local/lib/python3.13/site-packages/django/db/backends/utils.py", line 122, in execute
    return super().execute(sql, params)
           ~~~~~~~~~~~~~~~^^^^^^^^^^^^^
  File "/usr/local/lib/python3.13/site-packages/django/db/backends/utils.py", line 79, in execute
    return self._execute_with_wrappers(
           ~~~~~~~~~~~~~~~~~~~~~~~~~~~^
        sql, params, many=False, executor=self._execute
        ^^^^^^^^^^^^^^^^^^^^^^^^^^^^^^^^^^^^^^^^^^^^^^^
    )
    ^
  File "/usr/local/lib/python3.13/site-packages/django/db/backends/utils.py", line 92, in _execute_with_wrappers
    return executor(sql, params, many, context)
  File "/usr/local/lib/python3.13/site-packages/django/db/backends/utils.py", line 100, in _execute
    with self.db.wrap_database_errors:
         ^^^^^^^^^^^^^^^^^^^^^^^^^^^^
  File "/usr/local/lib/python3.13/site-packages/django/db/utils.py", line 91, in __exit__
    raise dj_exc_value.with_traceback(traceback) from exc_value
  File "/usr/local/lib/python3.13/site-packages/django/db/backends/utils.py", line 105, in _execute
    return self.cursor.execute(sql, params)
           ~~~~~~~~~~~~~~~~~~~^^^^^^^^^^^^^
  File "/usr/local/lib/python3.13/site-packages/django/db/backends/sqlite3/base.py", line 354, in execute
    return super().execute(query, params)
           ~~~~~~~~~~~~~~~^^^^^^^^^^^^^^^
django.db.utils.OperationalError: no such table: common_userprofile
ERROR 2024-12-08 14:37:29,561 basehttp "GET /common/currentuser/ HTTP/1.1" 500 158902
ERROR 2024-12-08 14:41:22,512 log Internal Server Error: /common/currentuser/
Traceback (most recent call last):
  File "/usr/local/lib/python3.13/site-packages/django/core/handlers/exception.py", line 55, in inner
    response = get_response(request)
  File "/usr/local/lib/python3.13/site-packages/django/core/handlers/base.py", line 197, in _get_response
    response = wrapped_callback(request, *callback_args, **callback_kwargs)
  File "/usr/local/lib/python3.13/site-packages/django/views/decorators/csrf.py", line 65, in _view_wrapper
    return view_func(request, *args, **kwargs)
  File "/usr/local/lib/python3.13/site-packages/django/views/generic/base.py", line 104, in view
    return self.dispatch(request, *args, **kwargs)
           ~~~~~~~~~~~~~^^^^^^^^^^^^^^^^^^^^^^^^^^
  File "/usr/local/lib/python3.13/site-packages/rest_framework/views.py", line 509, in dispatch
    response = self.handle_exception(exc)
  File "/usr/local/lib/python3.13/site-packages/rest_framework/views.py", line 469, in handle_exception
    self.raise_uncaught_exception(exc)
    ~~~~~~~~~~~~~~~~~~~~~~~~~~~~~^^^^^
  File "/usr/local/lib/python3.13/site-packages/rest_framework/views.py", line 480, in raise_uncaught_exception
    raise exc
  File "/usr/local/lib/python3.13/site-packages/rest_framework/views.py", line 506, in dispatch
    response = handler(request, *args, **kwargs)
  File "/app/common/views.py", line 89, in get
    userprofile = UserProfile.objects.get(user=user)
  File "/usr/local/lib/python3.13/site-packages/django/db/models/manager.py", line 87, in manager_method
    return getattr(self.get_queryset(), name)(*args, **kwargs)
           ~~~~~~~~~~~~~~~~~~~~~~~~~~~~~~~~~~^^^^^^^^^^^^^^^^^
  File "/usr/local/lib/python3.13/site-packages/django/db/models/query.py", line 649, in get
    raise self.model.DoesNotExist(
        "%s matching query does not exist." % self.model._meta.object_name
    )
common.models.UserProfile.DoesNotExist: UserProfile matching query does not exist.
ERROR 2024-12-08 14:41:22,521 basehttp "GET /common/currentuser/ HTTP/1.1" 500 95061
ERROR 2024-12-08 14:45:28,111 log Internal Server Error: /common/currentuser/
Traceback (most recent call last):
  File "/usr/local/lib/python3.13/site-packages/django/core/handlers/exception.py", line 55, in inner
    response = get_response(request)
  File "/usr/local/lib/python3.13/site-packages/django/core/handlers/base.py", line 197, in _get_response
    response = wrapped_callback(request, *callback_args, **callback_kwargs)
  File "/usr/local/lib/python3.13/site-packages/django/views/decorators/csrf.py", line 65, in _view_wrapper
    return view_func(request, *args, **kwargs)
  File "/usr/local/lib/python3.13/site-packages/django/views/generic/base.py", line 104, in view
    return self.dispatch(request, *args, **kwargs)
           ~~~~~~~~~~~~~^^^^^^^^^^^^^^^^^^^^^^^^^^
  File "/usr/local/lib/python3.13/site-packages/rest_framework/views.py", line 509, in dispatch
    response = self.handle_exception(exc)
  File "/usr/local/lib/python3.13/site-packages/rest_framework/views.py", line 469, in handle_exception
    self.raise_uncaught_exception(exc)
    ~~~~~~~~~~~~~~~~~~~~~~~~~~~~~^^^^^
  File "/usr/local/lib/python3.13/site-packages/rest_framework/views.py", line 480, in raise_uncaught_exception
    raise exc
  File "/usr/local/lib/python3.13/site-packages/rest_framework/views.py", line 506, in dispatch
    response = handler(request, *args, **kwargs)
  File "/app/common/views.py", line 89, in get
    userprofile = UserProfile.objects.get(user=user)
  File "/usr/local/lib/python3.13/site-packages/django/db/models/manager.py", line 87, in manager_method
    return getattr(self.get_queryset(), name)(*args, **kwargs)
           ~~~~~~~~~~~~~~~~~~~~~~~~~~~~~~~~~~^^^^^^^^^^^^^^^^^
  File "/usr/local/lib/python3.13/site-packages/django/db/models/query.py", line 649, in get
    raise self.model.DoesNotExist(
        "%s matching query does not exist." % self.model._meta.object_name
    )
common.models.UserProfile.DoesNotExist: UserProfile matching query does not exist.
ERROR 2024-12-08 14:45:28,134 basehttp "GET /common/currentuser/ HTTP/1.1" 500 95061
