INFO 2024-12-08 14:15:21,646 autoreload Watching for file changes with StatReloader
INFO 2024-12-08 14:26:06,636 autoreload Watching for file changes with StatReloader
WARNING 2024-12-08 14:26:15,955 log Not Found: /
WARNING 2024-12-08 14:26:15,957 basehttp "GET / HTTP/1.1" 404 2450
WARNING 2024-12-08 14:26:16,243 log Not Found: /favicon.ico
WARNING 2024-12-08 14:26:16,244 basehttp "GET /favicon.ico HTTP/1.1" 404 2501
INFO 2024-12-08 14:26:40,297 basehttp "OPTIONS /common/login/ HTTP/1.1" 200 0
INFO 2024-12-08 14:26:40,789 basehttp "POST /common/login/ HTTP/1.1" 200 321
WARNING 2024-12-08 14:27:15,609 log Bad Request: /common/login/
WARNING 2024-12-08 14:27:15,611 basehttp "POST /common/login/ HTTP/1.1" 400 32
INFO 2024-12-08 14:28:05,063 basehttp "POST /common/login/ HTTP/1.1" 200 321
INFO 2024-12-08 14:28:14,091 backends Cookie Auth: User abinj2003@gmail.com (ID: 70e2dc2a-1a0f-41c7-a609-261a9b5b9778) authenticated successfully
ERROR 2024-12-08 14:28:14,171 log Internal Server Error: /common/currentuser/
Traceback (most recent call last):
  File "/usr/local/lib/python3.13/site-packages/django/db/backends/utils.py", line 105, in _execute
    return self.cursor.execute(sql, params)
           ~~~~~~~~~~~~~~~~~~~^^^^^^^^^^^^^
  File "/usr/local/lib/python3.13/site-packages/django/db/backends/sqlite3/base.py", line 354, in execute
    return super().execute(query, params)
           ~~~~~~~~~~~~~~~^^^^^^^^^^^^^^^
sqlite3.OperationalError: no such table: common_userprofile

The above exception was the direct cause of the following exception:

Traceback (most recent call last):
  File "/usr/local/lib/python3.13/site-packages/django/core/handlers/exception.py", line 55, in inner
    response = get_response(request)
  File "/usr/local/lib/python3.13/site-packages/django/core/handlers/base.py", line 197, in _get_response
    response = wrapped_callback(request, *callback_args, **callback_kwargs)
  File "/usr/local/lib/python3.13/site-packages/django/views/decorators/csrf.py", line 65, in _view_wrapper
    return view_func(request, *args, **kwargs)
  File "/usr/local/lib/python3.13/site-packages/django/views/generic/base.py", line 104, in view
    return self.dispatch(request, *args, **kwargs)
           ~~~~~~~~~~~~~^^^^^^^^^^^^^^^^^^^^^^^^^^
  File "/usr/local/lib/python3.13/site-packages/rest_framework/views.py", line 509, in dispatch
    response = self.handle_exception(exc)
  File "/usr/local/lib/python3.13/site-packages/rest_framework/views.py", line 469, in handle_exception
    self.raise_uncaught_exception(exc)
    ~~~~~~~~~~~~~~~~~~~~~~~~~~~~~^^^^^
  File "/usr/local/lib/python3.13/site-packages/rest_framework/views.py", line 480, in raise_uncaught_exception
    raise exc
  File "/usr/local/lib/python3.13/site-packages/rest_framework/views.py", line 506, in dispatch
    response = handler(request, *args, **kwargs)
  File "/app/common/views.py", line 89, in get
    userprofile = UserProfile.objects.get(user=user)
  File "/usr/local/lib/python3.13/site-packages/django/db/models/manager.py", line 87, in manager_method
    return getattr(self.get_queryset(), name)(*args, **kwargs)
           ~~~~~~~~~~~~~~~~~~~~~~~~~~~~~~~~~~^^^^^^^^^^^^^^^^^
  File "/usr/local/lib/python3.13/site-packages/django/db/models/query.py", line 645, in get
    num = len(clone)
  File "/usr/local/lib/python3.13/site-packages/django/db/models/query.py", line 382, in __len__
    self._fetch_all()
    ~~~~~~~~~~~~~~~^^
  File "/usr/local/lib/python3.13/site-packages/django/db/models/query.py", line 1928, in _fetch_all
    self._result_cache = list(self._iterable_class(self))
                         ~~~~^^^^^^^^^^^^^^^^^^^^^^^^^^^^
  File "/usr/local/lib/python3.13/site-packages/django/db/models/query.py", line 91, in __iter__
    results = compiler.execute_sql(
        chunked_fetch=self.chunked_fetch, chunk_size=self.chunk_size
    )
  File "/usr/local/lib/python3.13/site-packages/django/db/models/sql/compiler.py", line 1574, in execute_sql
    cursor.execute(sql, params)
    ~~~~~~~~~~~~~~^^^^^^^^^^^^^
  File "/usr/local/lib/python3.13/site-packages/django/db/backends/utils.py", line 122, in execute
    return super().execute(sql, params)
           ~~~~~~~~~~~~~~~^^^^^^^^^^^^^
  File "/usr/local/lib/python3.13/site-packages/django/db/backends/utils.py", line 79, in execute
    return self._execute_with_wrappers(
           ~~~~~~~~~~~~~~~~~~~~~~~~~~~^
        sql, params, many=False, executor=self._execute
        ^^^^^^^^^^^^^^^^^^^^^^^^^^^^^^^^^^^^^^^^^^^^^^^
    )
    ^
  File "/usr/local/lib/python3.13/site-packages/django/db/backends/utils.py", line 92, in _execute_with_wrappers
    return executor(sql, params, many, context)
  File "/usr/local/lib/python3.13/site-packages/django/db/backends/utils.py", line 100, in _execute
    with self.db.wrap_database_errors:
         ^^^^^^^^^^^^^^^^^^^^^^^^^^^^
  File "/usr/local/lib/python3.13/site-packages/django/db/utils.py", line 91, in __exit__
    raise dj_exc_value.with_traceback(traceback) from exc_value
  File "/usr/local/lib/python3.13/site-packages/django/db/backends/utils.py", line 105, in _execute
    return self.cursor.execute(sql, params)
           ~~~~~~~~~~~~~~~~~~~^^^^^^^^^^^^^
  File "/usr/local/lib/python3.13/site-packages/django/db/backends/sqlite3/base.py", line 354, in execute
    return super().execute(query, params)
           ~~~~~~~~~~~~~~~^^^^^^^^^^^^^^^
django.db.utils.OperationalError: no such table: common_userprofile
ERROR 2024-12-08 14:28:14,183 basehttp "GET /common/currentuser/ HTTP/1.1" 500 158902
INFO 2024-12-08 14:33:31,584 autoreload Watching for file changes with StatReloader
INFO 2024-12-08 14:36:31,671 backends Cookie Auth: User abinj2003@gmail.com (ID: 70e2dc2a-1a0f-41c7-a609-261a9b5b9778) authenticated successfully
ERROR 2024-12-08 14:36:31,726 log Internal Server Error: /common/currentuser/
Traceback (most recent call last):
  File "/usr/local/lib/python3.13/site-packages/django/db/backends/utils.py", line 105, in _execute
    return self.cursor.execute(sql, params)
           ~~~~~~~~~~~~~~~~~~~^^^^^^^^^^^^^
  File "/usr/local/lib/python3.13/site-packages/django/db/backends/sqlite3/base.py", line 354, in execute
    return super().execute(query, params)
           ~~~~~~~~~~~~~~~^^^^^^^^^^^^^^^
sqlite3.OperationalError: no such table: common_userprofile

The above exception was the direct cause of the following exception:

Traceback (most recent call last):
  File "/usr/local/lib/python3.13/site-packages/django/core/handlers/exception.py", line 55, in inner
    response = get_response(request)
  File "/usr/local/lib/python3.13/site-packages/django/core/handlers/base.py", line 197, in _get_response
    response = wrapped_callback(request, *callback_args, **callback_kwargs)
  File "/usr/local/lib/python3.13/site-packages/django/views/decorators/csrf.py", line 65, in _view_wrapper
    return view_func(request, *args, **kwargs)
  File "/usr/local/lib/python3.13/site-packages/django/views/generic/base.py", line 104, in view
    return self.dispatch(request, *args, **kwargs)
           ~~~~~~~~~~~~~^^^^^^^^^^^^^^^^^^^^^^^^^^
  File "/usr/local/lib/python3.13/site-packages/rest_framework/views.py", line 509, in dispatch
    response = self.handle_exception(exc)
  File "/usr/local/lib/python3.13/site-packages/rest_framework/views.py", line 469, in handle_exception
    self.raise_uncaught_exception(exc)
    ~~~~~~~~~~~~~~~~~~~~~~~~~~~~~^^^^^
  File "/usr/local/lib/python3.13/site-packages/rest_framework/views.py", line 480, in raise_uncaught_exception
    raise exc
  File "/usr/local/lib/python3.13/site-packages/rest_framework/views.py", line 506, in dispatch
    response = handler(request, *args, **kwargs)
  File "/app/common/views.py", line 89, in get
    userprofile = UserProfile.objects.get(user=user)
  File "/usr/local/lib/python3.13/site-packages/django/db/models/manager.py", line 87, in manager_method
    return getattr(self.get_queryset(), name)(*args, **kwargs)
           ~~~~~~~~~~~~~~~~~~~~~~~~~~~~~~~~~~^^^^^^^^^^^^^^^^^
  File "/usr/local/lib/python3.13/site-packages/django/db/models/query.py", line 645, in get
    num = len(clone)
  File "/usr/local/lib/python3.13/site-packages/django/db/models/query.py", line 382, in __len__
    self._fetch_all()
    ~~~~~~~~~~~~~~~^^
  File "/usr/local/lib/python3.13/site-packages/django/db/models/query.py", line 1928, in _fetch_all
    self._result_cache = list(self._iterable_class(self))
                         ~~~~^^^^^^^^^^^^^^^^^^^^^^^^^^^^
  File "/usr/local/lib/python3.13/site-packages/django/db/models/query.py", line 91, in __iter__
    results = compiler.execute_sql(
        chunked_fetch=self.chunked_fetch, chunk_size=self.chunk_size
    )
  File "/usr/local/lib/python3.13/site-packages/django/db/models/sql/compiler.py", line 1574, in execute_sql
    cursor.execute(sql, params)
    ~~~~~~~~~~~~~~^^^^^^^^^^^^^
  File "/usr/local/lib/python3.13/site-packages/django/db/backends/utils.py", line 122, in execute
    return super().execute(sql, params)
           ~~~~~~~~~~~~~~~^^^^^^^^^^^^^
  File "/usr/local/lib/python3.13/site-packages/django/db/backends/utils.py", line 79, in execute
    return self._execute_with_wrappers(
           ~~~~~~~~~~~~~~~~~~~~~~~~~~~^
        sql, params, many=False, executor=self._execute
        ^^^^^^^^^^^^^^^^^^^^^^^^^^^^^^^^^^^^^^^^^^^^^^^
    )
    ^
  File "/usr/local/lib/python3.13/site-packages/django/db/backends/utils.py", line 92, in _execute_with_wrappers
    return executor(sql, params, many, context)
  File "/usr/local/lib/python3.13/site-packages/django/db/backends/utils.py", line 100, in _execute
    with self.db.wrap_database_errors:
         ^^^^^^^^^^^^^^^^^^^^^^^^^^^^
  File "/usr/local/lib/python3.13/site-packages/django/db/utils.py", line 91, in __exit__
    raise dj_exc_value.with_traceback(traceback) from exc_value
  File "/usr/local/lib/python3.13/site-packages/django/db/backends/utils.py", line 105, in _execute
    return self.cursor.execute(sql, params)
           ~~~~~~~~~~~~~~~~~~~^^^^^^^^^^^^^
  File "/usr/local/lib/python3.13/site-packages/django/db/backends/sqlite3/base.py", line 354, in execute
    return super().execute(query, params)
           ~~~~~~~~~~~~~~~^^^^^^^^^^^^^^^
django.db.utils.OperationalError: no such table: common_userprofile
ERROR 2024-12-08 14:36:31,735 basehttp "GET /common/currentuser/ HTTP/1.1" 500 158902
INFO 2024-12-08 14:36:42,423 basehttp "POST /common/login/ HTTP/1.1" 200 321
INFO 2024-12-08 14:37:29,489 backends Cookie Auth: User abinj2003@gmail.com (ID: 70e2dc2a-1a0f-41c7-a609-261a9b5b9778) authenticated successfully
ERROR 2024-12-08 14:37:29,551 log Internal Server Error: /common/currentuser/
Traceback (most recent call last):
  File "/usr/local/lib/python3.13/site-packages/django/db/backends/utils.py", line 105, in _execute
    return self.cursor.execute(sql, params)
           ~~~~~~~~~~~~~~~~~~~^^^^^^^^^^^^^
  File "/usr/local/lib/python3.13/site-packages/django/db/backends/sqlite3/base.py", line 354, in execute
    return super().execute(query, params)
           ~~~~~~~~~~~~~~~^^^^^^^^^^^^^^^
sqlite3.OperationalError: no such table: common_userprofile

The above exception was the direct cause of the following exception:

Traceback (most recent call last):
  File "/usr/local/lib/python3.13/site-packages/django/core/handlers/exception.py", line 55, in inner
    response = get_response(request)
  File "/usr/local/lib/python3.13/site-packages/django/core/handlers/base.py", line 197, in _get_response
    response = wrapped_callback(request, *callback_args, **callback_kwargs)
  File "/usr/local/lib/python3.13/site-packages/django/views/decorators/csrf.py", line 65, in _view_wrapper
    return view_func(request, *args, **kwargs)
  File "/usr/local/lib/python3.13/site-packages/django/views/generic/base.py", line 104, in view
    return self.dispatch(request, *args, **kwargs)
           ~~~~~~~~~~~~~^^^^^^^^^^^^^^^^^^^^^^^^^^
  File "/usr/local/lib/python3.13/site-packages/rest_framework/views.py", line 509, in dispatch
    response = self.handle_exception(exc)
  File "/usr/local/lib/python3.13/site-packages/rest_framework/views.py", line 469, in handle_exception
    self.raise_uncaught_exception(exc)
    ~~~~~~~~~~~~~~~~~~~~~~~~~~~~~^^^^^
  File "/usr/local/lib/python3.13/site-packages/rest_framework/views.py", line 480, in raise_uncaught_exception
    raise exc
  File "/usr/local/lib/python3.13/site-packages/rest_framework/views.py", line 506, in dispatch
    response = handler(request, *args, **kwargs)
  File "/app/common/views.py", line 89, in get
    userprofile = UserProfile.objects.get(user=user)
  File "/usr/local/lib/python3.13/site-packages/django/db/models/manager.py", line 87, in manager_method
    return getattr(self.get_queryset(), name)(*args, **kwargs)
           ~~~~~~~~~~~~~~~~~~~~~~~~~~~~~~~~~~^^^^^^^^^^^^^^^^^
  File "/usr/local/lib/python3.13/site-packages/django/db/models/query.py", line 645, in get
    num = len(clone)
  File "/usr/local/lib/python3.13/site-packages/django/db/models/query.py", line 382, in __len__
    self._fetch_all()
    ~~~~~~~~~~~~~~~^^
  File "/usr/local/lib/python3.13/site-packages/django/db/models/query.py", line 1928, in _fetch_all
    self._result_cache = list(self._iterable_class(self))
                         ~~~~^^^^^^^^^^^^^^^^^^^^^^^^^^^^
  File "/usr/local/lib/python3.13/site-packages/django/db/models/query.py", line 91, in __iter__
    results = compiler.execute_sql(
        chunked_fetch=self.chunked_fetch, chunk_size=self.chunk_size
    )
  File "/usr/local/lib/python3.13/site-packages/django/db/models/sql/compiler.py", line 1574, in execute_sql
    cursor.execute(sql, params)
    ~~~~~~~~~~~~~~^^^^^^^^^^^^^
  File "/usr/local/lib/python3.13/site-packages/django/db/backends/utils.py", line 122, in execute
    return super().execute(sql, params)
           ~~~~~~~~~~~~~~~^^^^^^^^^^^^^
  File "/usr/local/lib/python3.13/site-packages/django/db/backends/utils.py", line 79, in execute
    return self._execute_with_wrappers(
           ~~~~~~~~~~~~~~~~~~~~~~~~~~~^
        sql, params, many=False, executor=self._execute
        ^^^^^^^^^^^^^^^^^^^^^^^^^^^^^^^^^^^^^^^^^^^^^^^
    )
    ^
  File "/usr/local/lib/python3.13/site-packages/django/db/backends/utils.py", line 92, in _execute_with_wrappers
    return executor(sql, params, many, context)
  File "/usr/local/lib/python3.13/site-packages/django/db/backends/utils.py", line 100, in _execute
    with self.db.wrap_database_errors:
         ^^^^^^^^^^^^^^^^^^^^^^^^^^^^
  File "/usr/local/lib/python3.13/site-packages/django/db/utils.py", line 91, in __exit__
    raise dj_exc_value.with_traceback(traceback) from exc_value
  File "/usr/local/lib/python3.13/site-packages/django/db/backends/utils.py", line 105, in _execute
    return self.cursor.execute(sql, params)
           ~~~~~~~~~~~~~~~~~~~^^^^^^^^^^^^^
  File "/usr/local/lib/python3.13/site-packages/django/db/backends/sqlite3/base.py", line 354, in execute
    return super().execute(query, params)
           ~~~~~~~~~~~~~~~^^^^^^^^^^^^^^^
django.db.utils.OperationalError: no such table: common_userprofile
ERROR 2024-12-08 14:37:29,561 basehttp "GET /common/currentuser/ HTTP/1.1" 500 158902
INFO 2024-12-08 14:40:54,770 basehttp "POST /common/signup/ HTTP/1.1" 201 88
INFO 2024-12-08 14:41:15,257 basehttp "POST /common/login/ HTTP/1.1" 200 321
INFO 2024-12-08 14:41:22,431 backends Cookie Auth: User maneeshmanu929@gmail.com (ID: f63bff92-e9b5-4051-a266-06929a164c53) authenticated successfully
ERROR 2024-12-08 14:41:22,512 log Internal Server Error: /common/currentuser/
Traceback (most recent call last):
  File "/usr/local/lib/python3.13/site-packages/django/core/handlers/exception.py", line 55, in inner
    response = get_response(request)
  File "/usr/local/lib/python3.13/site-packages/django/core/handlers/base.py", line 197, in _get_response
    response = wrapped_callback(request, *callback_args, **callback_kwargs)
  File "/usr/local/lib/python3.13/site-packages/django/views/decorators/csrf.py", line 65, in _view_wrapper
    return view_func(request, *args, **kwargs)
  File "/usr/local/lib/python3.13/site-packages/django/views/generic/base.py", line 104, in view
    return self.dispatch(request, *args, **kwargs)
           ~~~~~~~~~~~~~^^^^^^^^^^^^^^^^^^^^^^^^^^
  File "/usr/local/lib/python3.13/site-packages/rest_framework/views.py", line 509, in dispatch
    response = self.handle_exception(exc)
  File "/usr/local/lib/python3.13/site-packages/rest_framework/views.py", line 469, in handle_exception
    self.raise_uncaught_exception(exc)
    ~~~~~~~~~~~~~~~~~~~~~~~~~~~~~^^^^^
  File "/usr/local/lib/python3.13/site-packages/rest_framework/views.py", line 480, in raise_uncaught_exception
    raise exc
  File "/usr/local/lib/python3.13/site-packages/rest_framework/views.py", line 506, in dispatch
    response = handler(request, *args, **kwargs)
  File "/app/common/views.py", line 89, in get
    userprofile = UserProfile.objects.get(user=user)
  File "/usr/local/lib/python3.13/site-packages/django/db/models/manager.py", line 87, in manager_method
    return getattr(self.get_queryset(), name)(*args, **kwargs)
           ~~~~~~~~~~~~~~~~~~~~~~~~~~~~~~~~~~^^^^^^^^^^^^^^^^^
  File "/usr/local/lib/python3.13/site-packages/django/db/models/query.py", line 649, in get
    raise self.model.DoesNotExist(
        "%s matching query does not exist." % self.model._meta.object_name
    )
common.models.UserProfile.DoesNotExist: UserProfile matching query does not exist.
ERROR 2024-12-08 14:41:22,521 basehttp "GET /common/currentuser/ HTTP/1.1" 500 95061
WARNING 2024-12-08 14:44:52,851 log Bad Request: /common/signup/
WARNING 2024-12-08 14:44:52,855 basehttp "POST /common/signup/ HTTP/1.1" 400 57
INFO 2024-12-08 14:45:13,419 basehttp "POST /common/login/ HTTP/1.1" 200 321
INFO 2024-12-08 14:45:27,987 backends Cookie Auth: User maneeshmanu929@gmail.com (ID: f63bff92-e9b5-4051-a266-06929a164c53) authenticated successfully
ERROR 2024-12-08 14:45:28,111 log Internal Server Error: /common/currentuser/
Traceback (most recent call last):
  File "/usr/local/lib/python3.13/site-packages/django/core/handlers/exception.py", line 55, in inner
    response = get_response(request)
  File "/usr/local/lib/python3.13/site-packages/django/core/handlers/base.py", line 197, in _get_response
    response = wrapped_callback(request, *callback_args, **callback_kwargs)
  File "/usr/local/lib/python3.13/site-packages/django/views/decorators/csrf.py", line 65, in _view_wrapper
    return view_func(request, *args, **kwargs)
  File "/usr/local/lib/python3.13/site-packages/django/views/generic/base.py", line 104, in view
    return self.dispatch(request, *args, **kwargs)
           ~~~~~~~~~~~~~^^^^^^^^^^^^^^^^^^^^^^^^^^
  File "/usr/local/lib/python3.13/site-packages/rest_framework/views.py", line 509, in dispatch
    response = self.handle_exception(exc)
  File "/usr/local/lib/python3.13/site-packages/rest_framework/views.py", line 469, in handle_exception
    self.raise_uncaught_exception(exc)
    ~~~~~~~~~~~~~~~~~~~~~~~~~~~~~^^^^^
  File "/usr/local/lib/python3.13/site-packages/rest_framework/views.py", line 480, in raise_uncaught_exception
    raise exc
  File "/usr/local/lib/python3.13/site-packages/rest_framework/views.py", line 506, in dispatch
    response = handler(request, *args, **kwargs)
  File "/app/common/views.py", line 89, in get
    userprofile = UserProfile.objects.get(user=user)
  File "/usr/local/lib/python3.13/site-packages/django/db/models/manager.py", line 87, in manager_method
    return getattr(self.get_queryset(), name)(*args, **kwargs)
           ~~~~~~~~~~~~~~~~~~~~~~~~~~~~~~~~~~^^^^^^^^^^^^^^^^^
  File "/usr/local/lib/python3.13/site-packages/django/db/models/query.py", line 649, in get
    raise self.model.DoesNotExist(
        "%s matching query does not exist." % self.model._meta.object_name
    )
common.models.UserProfile.DoesNotExist: UserProfile matching query does not exist.
ERROR 2024-12-08 14:45:28,134 basehttp "GET /common/currentuser/ HTTP/1.1" 500 95061
INFO 2024-12-08 14:48:31,363 backends Cookie Auth: User maneeshmanu929@gmail.com (ID: f63bff92-e9b5-4051-a266-06929a164c53) authenticated successfully
INFO 2024-12-08 14:48:31,401 basehttp "POST /common/user-profile/ HTTP/1.1" 201 88
INFO 2024-12-08 14:48:48,970 backends Cookie Auth: User maneeshmanu929@gmail.com (ID: f63bff92-e9b5-4051-a266-06929a164c53) authenticated successfully
INFO 2024-12-08 14:48:48,972 basehttp "GET /common/currentuser/ HTTP/1.1" 200 176
INFO 2024-12-08 14:59:50,403 basehttp "OPTIONS /common/signup/ HTTP/1.1" 200 0
INFO 2024-12-08 14:59:51,066 basehttp "POST /common/signup/ HTTP/1.1" 201 88
INFO 2024-12-08 15:00:04,681 basehttp "OPTIONS /common/forgot-password/ HTTP/1.1" 200 0
INFO 2024-12-08 15:00:06,955 basehttp "POST /common/forgot-password/ HTTP/1.1" 200 44
INFO 2024-12-08 15:04:43,528 autoreload /app/root/settings.py changed, reloading.
INFO 2024-12-08 15:04:45,133 autoreload Watching for file changes with StatReloader
INFO 2024-12-08 15:06:58,024 autoreload Watching for file changes with StatReloader
INFO 2024-12-08 15:08:25,663 basehttp "POST /common/forgot-password/ HTTP/1.1" 200 44
INFO 2024-12-08 15:08:26,363 basehttp "POST /common/forgot-password/ HTTP/1.1" 200 44
INFO 2024-12-08 15:09:12,879 basehttp "OPTIONS /common/verify-otp/ HTTP/1.1" 200 0
WARNING 2024-12-08 15:09:12,883 log Bad Request: /common/verify-otp/
WARNING 2024-12-08 15:09:12,883 basehttp "POST /common/verify-otp/ HTTP/1.1" 400 77
WARNING 2024-12-08 15:09:19,087 log Bad Request: /common/verify-otp/
WARNING 2024-12-08 15:09:19,087 basehttp "POST /common/verify-otp/ HTTP/1.1" 400 77
WARNING 2024-12-08 15:09:20,317 log Bad Request: /common/verify-otp/
WARNING 2024-12-08 15:09:20,318 basehttp "POST /common/verify-otp/ HTTP/1.1" 400 77
INFO 2024-12-09 03:37:59,718 autoreload Watching for file changes with StatReloader
INFO 2024-12-09 07:26:35,569 autoreload Watching for file changes with StatReloader
INFO 2024-12-09 07:29:23,097 autoreload Watching for file changes with StatReloader
INFO 2024-12-09 07:29:34,834 basehttp "OPTIONS /common/forgot-password/ HTTP/1.1" 200 0
INFO 2024-12-09 07:29:37,933 basehttp "POST /common/forgot-password/ HTTP/1.1" 200 44
INFO 2024-12-09 07:30:05,441 basehttp "OPTIONS /common/verify-otp/ HTTP/1.1" 200 0
WARNING 2024-12-09 07:30:05,442 log Bad Request: /common/verify-otp/
WARNING 2024-12-09 07:30:05,443 basehttp "POST /common/verify-otp/ HTTP/1.1" 400 77
WARNING 2024-12-09 07:30:09,971 log Bad Request: /common/verify-otp/
WARNING 2024-12-09 07:30:09,972 basehttp "POST /common/verify-otp/ HTTP/1.1" 400 77
WARNING 2024-12-09 07:30:10,120 log Bad Request: /common/verify-otp/
WARNING 2024-12-09 07:30:10,120 basehttp "POST /common/verify-otp/ HTTP/1.1" 400 77
WARNING 2024-12-09 07:30:11,173 log Bad Request: /common/verify-otp/
WARNING 2024-12-09 07:30:11,173 basehttp "POST /common/verify-otp/ HTTP/1.1" 400 77
WARNING 2024-12-09 07:30:11,359 log Bad Request: /common/verify-otp/
WARNING 2024-12-09 07:30:11,360 basehttp "POST /common/verify-otp/ HTTP/1.1" 400 77
WARNING 2024-12-09 07:30:15,852 log Bad Request: /common/verify-otp/
WARNING 2024-12-09 07:30:15,853 basehttp "POST /common/verify-otp/ HTTP/1.1" 400 77
WARNING 2024-12-09 07:30:16,541 log Bad Request: /common/verify-otp/
WARNING 2024-12-09 07:30:16,541 basehttp "POST /common/verify-otp/ HTTP/1.1" 400 77
INFO 2024-12-09 07:47:21,292 basehttp "OPTIONS /common/forgot-password/ HTTP/1.1" 200 0
WARNING 2024-12-09 07:47:21,300 log Bad Request: /common/forgot-password/
WARNING 2024-12-09 07:47:21,300 basehttp "POST /common/forgot-password/ HTTP/1.1" 400 70
INFO 2024-12-09 07:47:53,916 basehttp "POST /common/forgot-password/ HTTP/1.1" 200 44
INFO 2024-12-09 07:48:11,957 basehttp "POST /common/forgot-password/ HTTP/1.1" 200 44
WARNING 2024-12-09 07:48:14,940 log Bad Request: /common/forgot-password/
WARNING 2024-12-09 07:48:14,940 basehttp "POST /common/forgot-password/ HTTP/1.1" 400 98
WARNING 2024-12-09 07:48:18,000 log Bad Request: /common/forgot-password/
WARNING 2024-12-09 07:48:18,000 basehttp "POST /common/forgot-password/ HTTP/1.1" 400 98
INFO 2024-12-10 02:44:47,448 autoreload Watching for file changes with StatReloader
INFO 2024-12-10 18:02:16,124 basehttp "OPTIONS /common/forgot-password/ HTTP/1.1" 200 0
WARNING 2024-12-10 18:02:16,225 log Bad Request: /common/forgot-password/
WARNING 2024-12-10 18:02:16,257 basehttp "POST /common/forgot-password/ HTTP/1.1" 400 70
WARNING 2024-12-10 18:02:21,669 log Bad Request: /common/forgot-password/
WARNING 2024-12-10 18:02:21,670 basehttp "POST /common/forgot-password/ HTTP/1.1" 400 88
INFO 2024-12-10 18:04:27,818 autoreload Watching for file changes with StatReloader
INFO 2024-12-10 18:05:21,015 basehttp "OPTIONS /common/forgot-password/ HTTP/1.1" 200 0
INFO 2024-12-10 18:05:24,712 basehttp "POST /common/forgot-password/ HTTP/1.1" 200 44
INFO 2024-12-10 18:06:10,124 basehttp "OPTIONS /common/verify-otp/ HTTP/1.1" 200 0
WARNING 2024-12-10 18:06:10,139 log Bad Request: /common/verify-otp/
WARNING 2024-12-10 18:06:10,139 basehttp "POST /common/verify-otp/ HTTP/1.1" 400 77
WARNING 2024-12-10 18:06:31,330 log Bad Request: /common/verify-otp/
WARNING 2024-12-10 18:06:31,333 basehttp "POST /common/verify-otp/ HTTP/1.1" 400 77
WARNING 2024-12-10 18:06:42,728 log Bad Request: /common/verify-otp/
WARNING 2024-12-10 18:06:42,728 basehttp "POST /common/verify-otp/ HTTP/1.1" 400 77
INFO 2024-12-10 18:08:49,775 autoreload Watching for file changes with StatReloader
INFO 2024-12-10 18:09:32,082 basehttp "OPTIONS /common/forgot-password/ HTTP/1.1" 200 0
WARNING 2024-12-10 18:09:32,501 log Bad Request: /common/forgot-password/
WARNING 2024-12-10 18:09:32,501 basehttp "POST /common/forgot-password/ HTTP/1.1" 400 98
INFO 2024-12-10 18:09:35,360 basehttp "POST /common/forgot-password/ HTTP/1.1" 200 44
INFO 2024-12-10 18:09:35,462 basehttp "POST /common/forgot-password/ HTTP/1.1" 200 44
INFO 2024-12-10 18:10:12,711 basehttp "OPTIONS /common/verify-otp/ HTTP/1.1" 200 0
WARNING 2024-12-10 18:10:12,714 log Bad Request: /common/verify-otp/
WARNING 2024-12-10 18:10:12,714 basehttp "POST /common/verify-otp/ HTTP/1.1" 400 77
WARNING 2024-12-10 18:10:33,002 log Bad Request: /common/verify-otp/
WARNING 2024-12-10 18:10:33,004 basehttp "POST /common/verify-otp/ HTTP/1.1" 400 77
INFO 2024-12-10 18:14:22,015 autoreload Watching for file changes with StatReloader
WARNING 2024-12-10 18:20:30,576 log Bad Request: /common/forgot-password/
WARNING 2024-12-10 18:20:30,577 basehttp "POST /common/forgot-password/ HTTP/1.1" 400 98
WARNING 2024-12-10 18:20:34,068 log Bad Request: /common/forgot-password/
WARNING 2024-12-10 18:20:34,069 basehttp "POST /common/forgot-password/ HTTP/1.1" 400 98
WARNING 2024-12-10 18:20:42,203 log Bad Request: /common/forgot-password/
WARNING 2024-12-10 18:20:42,203 basehttp "POST /common/forgot-password/ HTTP/1.1" 400 98
WARNING 2024-12-10 18:21:24,631 log Bad Request: /common/forgot-password/
WARNING 2024-12-10 18:21:24,635 basehttp "POST /common/forgot-password/ HTTP/1.1" 400 98
WARNING 2024-12-10 18:22:00,796 log Bad Request: /common/forgot-password/
WARNING 2024-12-10 18:22:00,798 basehttp "POST /common/forgot-password/ HTTP/1.1" 400 98
WARNING 2024-12-10 18:22:05,591 log Bad Request: /common/forgot-password/
WARNING 2024-12-10 18:22:05,592 basehttp "POST /common/forgot-password/ HTTP/1.1" 400 98
WARNING 2024-12-10 18:22:36,758 log Bad Request: /common/forgot-password/
WARNING 2024-12-10 18:22:36,758 basehttp "POST /common/forgot-password/ HTTP/1.1" 400 88
WARNING 2024-12-10 18:23:10,468 log Bad Request: /common/forgot-password/
WARNING 2024-12-10 18:23:10,469 basehttp "POST /common/forgot-password/ HTTP/1.1" 400 98
WARNING 2024-12-10 18:23:56,325 log Bad Request: /common/forgot-password/
WARNING 2024-12-10 18:23:56,326 basehttp "POST /common/forgot-password/ HTTP/1.1" 400 98
INFO 2024-12-10 18:26:47,570 autoreload Watching for file changes with StatReloader
WARNING 2024-12-10 18:27:52,383 log Bad Request: /common/forgot-password/
WARNING 2024-12-10 18:27:52,383 basehttp "POST /common/forgot-password/ HTTP/1.1" 400 98
INFO 2024-12-11 02:50:23,414 autoreload Watching for file changes with StatReloader
INFO 2024-12-11 08:09:48,884 autoreload Watching for file changes with StatReloader
INFO 2024-12-12 17:13:16,544 autoreload Watching for file changes with StatReloader
INFO 2024-12-13 03:43:24,291 autoreload Watching for file changes with StatReloader
INFO 2024-12-13 08:00:49,879 autoreload Watching for file changes with StatReloader
INFO 2024-12-14 02:50:40,809 autoreload Watching for file changes with StatReloader
INFO 2024-12-14 05:07:57,953 autoreload /app/common/handlers.py changed, reloading.
INFO 2024-12-14 05:07:59,637 autoreload Watching for file changes with StatReloader
INFO 2024-12-14 05:09:57,943 autoreload Watching for file changes with StatReloader
INFO 2024-12-14 05:11:15,433 autoreload Watching for file changes with StatReloader
WARNING 2024-12-14 05:12:19,153 backends No token found in cookies for authentication.
WARNING 2024-12-14 05:12:19,182 log Forbidden: /common/logout/
WARNING 2024-12-14 05:12:19,189 basehttp "POST /common/logout/ HTTP/1.1" 403 58
INFO 2024-12-14 05:12:46,510 basehttp "OPTIONS /common/forgot-password/ HTTP/1.1" 200 0
INFO 2024-12-14 05:12:50,771 basehttp "POST /common/forgot-password/ HTTP/1.1" 200 44
INFO 2024-12-14 05:13:38,752 basehttp "OPTIONS /common/verify-otp/ HTTP/1.1" 200 0
INFO 2024-12-14 05:13:39,466 basehttp "POST /common/verify-otp/ HTTP/1.1" 200 42
INFO 2024-12-14 05:13:52,457 basehttp "OPTIONS /common/login/ HTTP/1.1" 200 0
INFO 2024-12-14 05:13:53,161 basehttp "POST /common/login/ HTTP/1.1" 200 321
INFO 2024-12-14 05:14:08,768 backends Cookie Auth: User abinj2003@gmail.com (ID: cd0f8166-51fd-42e4-9b3b-3ab21b8c870e) authenticated successfully
INFO 2024-12-14 05:14:08,769 basehttp "POST /common/logout/ HTTP/1.1" 200 36
